Workbook
Name A1.: 'ABISINIA INSS'!$A$2213
Name A1.: 'ACOPIO ABISINIA'!$A$2204
Name A1.: 'ACOPIO EL CONSUELO'!$A$2205
Name A1.: 'ACOPIO ESCAMBRAY'!$A$2204
Name A1.: 'ACOPIO LAS MORENAS 2'!$A$2204
Name A1.: 'ACOPIO MONTECRISTO'!$A$2206
Name A1.: 'ACOPIO STA ISABEL'!$A$2204
Name A1.: 'ADMON COM. '!$A$2300
Name A1.: 'BODEG STA Isabel'!$A$2213
Name A1.: 'BODEGA-ACOPIO'!$A$2208
Name A1.: 'COMISARIATO INSS'!$A$2213
Name A1.: 'COMISARIATO SIN INSS'!$A$2209
Name A1.: 'FINANCIAMIENTO INSS'!$A$2211
Name A1.: FINCA!$A$2205
Name A1.: 'FINCA INSS '!$A$2225
Name A1.: 'FINCA SIN INSS'!$A$2216
Name A1.: 'PERS-ACOPIO STA ISABEL'!$A$2218
Name A1.: TECNICOS!$A$2208

Sheet DETALLE ADMON.
A1: AGRICOLA SANTA ISABEL
A2: QUINCENA DEL 16 AL 30 DE ABRIL 2026
A4: PLANILLA | B4: TOTAL | C4: FEMENINO | D4: MASCULINO | E4: CON INSS | F4: SIN INSS | G4: TOTAL NOMINA | H4: FINCA | I4: TOTAL A PAGAR | J4: COMISARIATO | K4: NETO A PAGAR
A5: ADMINISTRACION FINCA | E5: =+ADMON!X21 -> 36121.381 | G5: =+E5+F5 -> 36121.381 | H5: =+ADMON!Z21 -> 1500 | I5: =+G5-H5 -> 34621.381 | J5: =+ADMON!AB21 -> 808 | K5: =G5-H5-J5 -> 33813.381
A6: ADMINISTRACION COMERCIAL | B6: =+C6+D6 -> 7 | C6: =COUNTIF('ADMON COM. '!E18:E29,"F")+H!I16 -> 2 | D6: =COUNTIF('ADMON COM. '!E18:E29,"M")+H!J16 -> 5 | E6: =+'ADMON COM. '!T30 -> 57799.001 | F6: =+H!BP15 -> 0 | G6: =+E6+F6 -> 57799.001 | H6: =+'ADMON COM. '!V30 -> 500 | I6: =+G6-H6 -> 57299.001 | J6: 0 | K6: =G6-H6-J6 -> 57299.001
A7: FINCA SIN INSS | B7: =+C7+D7 -> 1 | C7: 0 | D7: 1 | E7: 0 | F7: =+'FINCA SIN INSS'!X15 -> 36647.945 | G7: =+E7+F7 -> 36647.945 | H7: ='FINCA SIN INSS'!Y15 -> 2500 | I7: ='FINCA SIN INSS'!Z15 -> 34147.945 | J7: =+'FINCA SIN INSS'!AA15 -> 2000 | K7: =G7-H7-J7 -> 32147.945
A8: FINCA CON INSS | E8: =+'FINCA INSS '!W17 -> 0 | F8: 0 | G8: =+E8+F8 -> 0 | H8: =+'FINCA INSS '!Z17 -> 0 | I8: =+G8-H8 -> 0 | J8: =+'FINCA INSS '!AC17 -> 195 | K8: =+I8-J8 -> -195
A9: BENEFICIO SECO SIN INSS | B9: =+C9+D9 -> 3 | C9: 2 | D9: 1 | E9: 0 | F9: =+'BENEFICIO SECO'!X13 -> 0 | G9: =+E9+F9 -> 0 | H9: =+'BENEFICIO SECO'!Y13 -> 0 | I9: =+G9-H9 -> 0 | J9: 0 | K9: =+I9-J9 -> 0
A10: COMPLEMENTO DE SALARIO | B10: =+C10+D10 -> 2 | C10: 1 | D10: 1 | E10: 0 | F10: =+'COMPLEMENTO DE SALARIO'!C12 -> 5009.2 | G10: =+E10+F10 -> 5009.2 | H10: ='COMPLEMENTO DE SALARIO'!D12 -> 0 | I10: =+G10-H10 -> 5009.2 | J10: =+'COMPLEMENTO DE SALARIO'!F12 -> 0 | K10: =G10-H10-J10 -> 5009.2
A11: EVENTUAL | E11: 0 | F11: =+EVENTUAL!C14 -> 36966.984 | G11: =E11+F11 -> 36966.984 | H11: =+EVENTUAL!D14 -> 0 | I11: =+G11-H11 -> 36966.984 | J11: 0 | K11: =G11-H11-J11 -> 36966.984
A12: ABISINIA-INSS | E12: =+'ABISINIA INSS'!Z12 -> 3664.53 | F12: 0 | G12: =E12+F12 -> 3664.53 | H12: 0 | I12: =+G12-H12 -> 3664.53 | J12: 0 | K12: =G12-H12-J12 -> 3664.53
A13: BODEGA DE ACOPIO | E13: ='BODEG STA Isabel'!W12 -> 4275 | F13: 0 | G13: =+E13+F13 -> 4275 | H13: ='BODEG STA Isabel'!Y12 -> 2000 | I13: =+G13-H13 -> 2275 | J13: =+#REF! -> #REF! | K13: =+I13-J13 -> #REF!
A14: ACOPIO MONTECRISTO | E14: 0 | F14: =+'ACOP MONTECRISTO'!X12 -> 0 | G14: =+E14+F14 -> 0 | H14: =+'ACOP MONTECRISTO'!Y12 -> 0 | I14: =+G14-H14 -> 0 | J14: =+'ACOP MONTECRISTO'!AB12 -> 0 | K14: =+I14-J14 -> 0
A15: ACOPIO LAS MORENAS | E15: 0 | F15: =+'ACOP LAS MORENAS'!X13 -> 0 | G15: =+E15+F15 -> 0 | H15: =+'ACOP LAS MORENAS'!Y13 -> 0 | I15: =+G15-H15 -> 0 | J15: 0 | K15: =+G15-H15-J15 -> 0
A16: ACOPIO ABISINIA SIN INSS | E16: 0 | F16: =+'ACOP ABISINIA SIN INSS'!X14 -> 0 | G16: =+E16+F16 -> 0 | H16: =+'ACOP ABISINIA SIN INSS'!Z14 -> 0 | I16: =+G16-H16 -> 0 | J16: 0 | K16: =+G16-H16-J16 -> 0
A17: ACOPIO EL CONSUELO | E17: 0 | F17: =+'ACOP EL CONSUELO'!X12 -> 0 | G17: =+E17+F17 -> 0 | H17: =+'ACOP EL CONSUELO'!Y12 -> 0 | I17: =+G17-H17 -> 0 | J17: 0 | K17: =+G17-H17-J17 -> 0
A18: VIATICOS PERSONAL DE ACOPIO | E18: 0 | F18: =+'VIATICOS ACOPIO'!F18 -> 0 | G18: =+E18+F18 -> 0 | H18: =+'ACOP LA UNION'!Y9 -> 0 | I18: =+G18-H18 -> 0 | J18: 0 | K18: =+G18-H18-J18 -> 0
E19: 0 | F19: 0 | G19: =+E19+F19 -> 0 | H19: 0 | I19: =+G19-H19 -> 0 | J19: 0 | K19: =+G19-H19-J19 -> 0
A20: COMPLEMENTO DE SALARIO EN RECIBO | E20: 0 | F20: 0 | G20: =+E20+F20 -> 0 | H20: 0 | I20: 0 | J20: 0 | K20: =+G20-H20-J20 -> 0
A21: PAGO DE VIAJE DE CAMIONERO | E21: 0 | F21: 0 | G21: =+E21+F21 -> 0 | H21: 0 | I21: 0 | J21: 0 | K21: =+G21-H21-J21 -> 0
A22: TOTAL | E22: =SUM(E5:E21) -> 101859.91 | F22: =SUM(F5:F21) -> 78624.129 | G22: =SUM(G5:G21) -> 180484.04 | H22: =SUM(H5:H21) -> 6500 | I22: =SUM(I5:I21) -> 173984.04 | J22: =SUM(J5:J21) -> #REF! | K22: =SUM(K5:K21) -> #REF!
N26: =G22-H22-J22 -> #REF!
A27: _______________________________ | E27: ______________________________________ | H27: ________________________________________________
A28: REVISADO | E28: AUTORIZADO | H28: IVAN OROZCO OSEJO
A29: Ivan Orozco Osejo | E29: Lic. Osman Gregorio Gutierrez Moreno | I29: Auxiliar Contable

Sheet Cambio del dia
F7: Dias | G7: Dólar
F8: 1
F9: 2
F10: 3
F11: 4
F12: 5
F13: 6
F14: 7
F15: 8
F16: 9
F17: 10
F18: 11
F19: 12
F20: 13
F21: 14 | G21: 0
F22: 15 | G22: 36.6243
F23: 16 | G23: 36.6243
F24: 17 | G24: 36.6243
F25: 18 | G25: 36.6243
F26: 19 | G26: 36.6243
F27: 20 | G27: 36.6243
F28: 21 | G28: 36.6243
F29: 22 | G29: 36.6243
F30: 23 | G30: 36.6243
F31: 24 | G31: 36.6243
F32: 25 | G32: 36.6243
... F38: 31 | G38: 36.6243
A44: No | B44: INSS | C44: NUMERO DE CEDULA | D44: NOMBRES Y APELLIDOS | E44: GENERO | F44: CARGO | G44: salario en dolares | H44: cambio del dia | I44: SALARIO MENSUAL | J44: I N G R E S O S | M44: RETENCIONES | Q44: TOTAL DEVENGADO | R44: ALIMENTACION | S44: FINCA | T44: COMISARIATO | U44: TOTAL A PAGAR | V44: FIRMAS | W44: VACACIONES | X44: 13vo mes | Y44: TOTAL GASTOS NOMINAS
J45: SALARIO QUINCENAL | K45: DIAS LABORADOS | L45: TOTAL INGRESOS | M45: INSS LABORAL | N45: IR | O45: ABONO RESTAMOS | P45: TOTAL RETENCION
A47: 1 | B47: 7288164 | C47: 241-250163-0005Q | D47: PASTOR DE JESUS CHAVARRIA HERRERA | E47: M | F47: CONTADOR GENERAL | G47: 1000 | H47: =+G38 -> 36.6243 | I47: =+G47*H47 -> 36624.3 | J47: =+I47/30*K47 -> 18312.15 | K47: 15 | L47: =+J47 -> 18312.15 | M47: 0 | N47: 0 | O47: 1090.524 | P47: 1090.524 | Q47: =+L47-O47 -> 17221.626 | S47: 0 | T47: 0 | U47: =+Q47 -> 17221.626 | V47: 1 | W47: 776.93777 | X47: 776.93777 | Y47: =+U47+W47+X47 -> 18775.502
A48: 2 | B48: 17814360 | C48: 288-210859-0001M | D48: PEDRO JOAQUIN HUETE | E48: M | F48: MANDADOR FINCA | G48: 510 | H48: =+G36 -> 36.6243 | I48: 18678.4 | J48: =+I48/30*K48 -> 9339.2 | K48: 15 | L48: =+J48 -> 9339.2 | M48: 0 | N48: 0 | O48: 0 | P48: 0 | Q48: =+L48 -> 9339.2 | R48: 0 | S48: 0 | T48: 0 | U48: =+Q48-S48 -> 9339.2 | V48: 3 | W48: 908.77 | X48: 908.77 | Y48: =+U48+W48+X48 -> 11156.74
A49: 3 | D49: YEMIN DAVID GUTIERREZ MORENO | E49: M | F49: DILLERO | G49: 182.08 | H49: 36.6243 | I49: =+G49*H49 -> 6668.5525 | J49: =+I49/30*K49 -> 3334.2763 | K49: 15 | L49: =+J49 -> 3334.2763 | O49: 0 | P49: 0 | Q49: =+L49 -> 3334.2763 | R49: 0 | U49: =+Q49-S49 -> 3334.2763 | W49: 908.77 | X49: 908.77 | Y49: =+U49+W49+X49 -> 5151.8163
A50: 4 | B50: 6983178 | C50: 601-120863-0000N | D50: JOAQUIN ENRRIQUE CASTILLO CARCACHE | E50: M | F50: TECNICO | G50: 350 | H50: =+G35 -> 36.6243 | I50: =+G50*H50 -> 12818.505 | J50: =+I50/30*K50 -> 6409.2525 | K50: 15 | L50: =+J50 -> 6409.2525 | M50: 0 | N50: 0 | O50: 0 | P50: 0 | Q50: =+L50 -> 6409.2525 | R50: 0 | S50: 0 | T50: 0 | U50: =+Q50-S50 -> 6409.2525 | V50: 3 | W50: 908.77 | X50: 908.77 | Y50: =+U50+W50+X50 -> 8226.7925
A51: 4 | B51: 6983178 | C51: 601-120863-0000N | D51: LUIS FERNANDO PALACIOS RIOS | E51: M | F51: TECNICO | G51: 350 | H51: =+G35 -> 36.6243 | I51: =+G51*H51 -> 12818.505 | J51: =+I51/30*K51 -> 6409.2525 | K51: 15 | L51: =+J51 -> 6409.2525 | M51: 0 | N51: 0 | O51: 0 | P51: 0 | Q51: =+L51 -> 6409.2525 | R51: 0 | S51: 0 | T51: 0 | U51: =+Q51-S51 -> 6409.2525 | V51: 3 | W51: 908.77 | X51: 908.77 | Y51: =+U51+W51+X51 -> 8226.7925
A52: 4 | B52: 6983178 | C52: 601-120863-0000N | D52: MARTIN CONRRADO RIZO | E52: M | F52: PLANILLAS | G52: 327.6515 | H52: =+G35 -> 36.6243 | I52: =+G52*H52 -> 12000.007 | J52: =+I52/30*K52 -> 6000.0034 | K52: 15 | L52: =+J52 -> 6000.0034 | M52: 0 | N52: 0 | O52: 0 | P52: 0 | Q52: =+L52 -> 6000.0034 | R52: 0 | S52: 0 | T52: 0 | U52: =+Q52-S52 -> 6000.0034 | V52: 3 | W52: 908.77 | X52: 908.77 | Y52: =+U52+W52+X52 -> 7817.5434
A53: 4 | B53: 6983178 | C53: 601-120863-0000N | D53: =+'ADMON COM. '!D20 -> NELLY DEL CARMEN SOBALVARRO THOMAS | E53: F | F53: TECNICO | G53: =+'ADMON COM. '!G20 -> 298.9818 | H53: =+G36 -> 36.6243 | I53: =+G53*H53 -> 10949.999 | J53: =+I53/30*K53 -> 5474.9996 | K53: 15 | L53: =+J53 -> 5474.9996 | M53: 0 | N53: 0 | O53: 0 | P53: 0 | Q53: =+L53 -> 5474.9996 | R53: 0 | S53: 0 | T53: 0 | U53: =+Q53-S53 -> 5474.9996 | V53: 3 | W53: 908.77 | X53: 908.77 | Y53: =+U53+W53+X53 -> 7292.5396
L54: 18

Sheet FINCA
A1: AGRÍCOLA SANTA ISABEL
A2: PLANILLA DE SALARIO QUINCENAL DE TÉCNICOS DE ACOPIO
A3: =+'ADMON COM. '!A5:AC5 -> QUINCENA DEL 16 AL 30 DE ABRIL - 2026
A4: =+'ADMON COM. '!A6 -> 15
A5: No | B5: INSS | C5: NUMERO DE CEDULA | D5: NOMBRES Y APELLIDOS | E5: GENERO | F5: CARGO | G5: salario en dolares | H5: cambio del dia | I5: SALARIO DIARIO | J5: SALARIO MENSUAL | K5: I N G R E S O S | Q5: RETENCIONES | U5: TOTAL | V5: ALIMENTACION | W5: FINCA | X5: COMISARIATO | Y5: SALARIO DEVENGADO | Z5: FIRMAS | AA5: VACASIONES | AB5: 13VO MES | AC5: INSS PATRONAL | AD5: INATEC 2% | AE5: TOTAL GASTOS NOMINAS
K6: SALARIO QUINCENAL | L6: DIAS LABORADOS | M6: total subcidio | N6: subcidio por dia | O6: DIAS SUBSIDIO | P6: TOTAL INGRESOS | Q6: INSS LABORAL | R6: IR | S6: ABONO POR PRESTAMOS | T6: TOTAL RETENCION
A8: 1 | B8: 5357574 | C8: 0 | D8: =+'ADMON COM. '!#REF! -> #REF! | E8: M | F8: ADMINISTRADOR | G8: 500 | H8: =LOOKUP(A4,'Cambio del dia'!F7:G38) -> 36.6243 | I8: =+K8/L8 -> #REF! | J8: =+H8*G8 -> 18312.15 | K8: =+(J8/30)*L8-'ADMON COM. '!#REF! -> #REF! | L8: 16 | M8: =+N8*O8 -> #REF! | N8: =I8*60% -> #REF! | O8: 0 | P8: =+K8-M8 -> #REF! | Q8: 0 | R8: 0 | T8: =+Q8+R8+S8 -> 0 | U8: =-T8+P8 -> #REF! | V8: 0 | Y8: =+P8 -> #REF! | AA8: =+J8/30*1.25 -> 763.00625 | AB8: =+J8/30*1.25 -> 763.00625 | AC8: =IF(B8="",0,P8*21.5%) -> #REF! | AD8: =IF(Q8>0,P8*2%,0) -> 0 | AE8: =SUM(P8,AC8,AB8,AA8,AD8) -> #REF!
A9: TOTALES | G9: =SUM(G8:G8) -> 500 | I9: =SUM(I8:I8) -> #REF! | J9: =SUM(J8:J8) -> 18312.15 | K9: =SUM(K8:K8) -> #REF! | L9: =SUM(L8:L8) -> 16 | M9: =+N9*O9 -> #REF! | N9: =I9*60% -> #REF! | O9: =SUM(O8:O8) -> 0 | P9: =SUM(P8:P8) -> #REF! | Q9: =SUM(Q8:Q8) -> 0 | R9: =SUM(R8:R8) -> 0 | S9: =SUM(S8:S8) -> 0 | T9: =SUM(T8:T8) -> 0 | U9: =SUM(U8:U8) -> #REF! | V9: =SUM(V8:V8) -> 0 | ... Y9: =SUM(Y8:Y8) -> #REF! | Z9: "EL SEÑOR ES MI PASTOR, NADA ME FALTARA" | AA9: =SUM(AA8:AA8) -> 763.00625 | AB9: =SUM(AB8:AB8) -> 763.00625 | AC9: =SUM(AC8:AC8) -> #REF! | AD9: =SUM(AD8:AD8) -> 0 | AE9: =SUM(AE8:AE8) -> #REF!
C20: ELABORADO POR: | L20: REVISADO POR: | Y20: AUTORIZADO POR:
C21: =+'ADMON COM. '!C50:F50 -> Jose Martin Conrrado | L21: Lic. Pastor de Jesús Chavarría Herrera | Y21: Lic. Osman Gregorio Gutiérrez Moreno

Sheet H
A3: JINOTEGA, NICARAGUA
A4: ACOPIO OSMAN GUTIERREZ
A5: PLANILLA DE SALARIO QUINCENAL PERSONAL ADMINISTRATIVO
A6: =+'COMISARIATO CON INSS'!A4 -> QUINCENA DEL 16 AL 30 DE ABRIL - 2026
A11: =+'ADMON COM. '!A6 -> 15
A12: No. | B12: SALARIO | C12: dolares | D12: cambio | E12: mensual | F12: 14cenal | G12: NOMBRES Y APELLIDOS | H12: SALARIO DIARIO | I12: GENERO | J12: Actividad | K12: =+'COMISARIATO CON INSS'!H7 -> 16 | L12: =+'COMISARIATO CON INSS'!I7 -> 17 | M12: =+'COMISARIATO CON INSS'!J7 -> 18 | N12: =+'COMISARIATO CON INSS'!K7 -> 19 | O12: =+'COMISARIATO CON INSS'!L7 -> 20 | P12: =+'COMISARIATO CON INSS'!M7 -> 21 | Q12: =+'COMISARIATO CON INSS'!N7 -> 22 | R12: 1 semana | S12: SEPTIMO DIA | T12: =+'COMISARIATO CON INSS'!Q7 -> 23 | U12: =+'COMISARIATO CON INSS'!R7 -> 24 | V12: =+'COMISARIATO CON INSS'!S7 -> 25 | W12: =+'COMISARIATO CON INSS'!T7 -> 26 | X12: =+'COMISARIATO CON INSS'!U7 -> 27 | Y12: =+'COMISARIATO CON INSS'!V7 -> 28 | Z12: =+'COMISARIATO CON INSS'!W7 -> 29 | AA12: =+'COMISARIATO CON INSS'!X7 -> 30 | AB12: 16 | AC12: 2 semana | AD12: SEPTIMO DIA | AE12: SUMA SETIMOS | AF12: SUMA DIAS | AG12: DIAS TRABAJADOS | AH12: FERIADOS/ LIBRES | AI12: HRS EXT | AJ12: DOM LAB | AK12: SALARIO BASICO | AN12: SEPTIMO DIA | AO12: COSTE DIA | AP12: COSTE HORA | AQ12: DOMINGOS TRABAJADOS | AR12: HORAS EXTRAS | AS12: DIAS FERIADOS | AT12: Extras y/o Dom. Trab | AU12: DIAS | AV12: SALARIO | AW12: DODIGO | AX12: CONSTANTE | AY12: SALARIO 14CENAL | AZ12: FORMUAL | BA12: FORMULA | BB12: FORMULA | BC12: TOTAOL | BD12: adicional | BE12: INGRESO BASICO | BG12: INSS | BH12: VACASIONES | BI12: 13VO MES | BJ12: TOTAL INGRESOS | BN12: SALARIO NETO | BO12: ALIMENTACION | BP12: NETO A PAGAR | BQ12: RECIBIDO CONFORME
K14: =+'COMISARIATO CON INSS'!H9 -> S | L14: =+'COMISARIATO CON INSS'!I9 -> D | M14: =+'COMISARIATO CON INSS'!J9 -> L | N14: =+'COMISARIATO CON INSS'!K9 -> M | O14: =+'COMISARIATO CON INSS'!L9 -> M | P14: =+'COMISARIATO CON INSS'!M9 -> J | Q14: =+'COMISARIATO CON INSS'!N9 -> V | T14: =+'COMISARIATO CON INSS'!Q9 -> S | U14: =+'COMISARIATO CON INSS'!R9 -> D | V14: =+'COMISARIATO CON INSS'!S9 -> L | W14: =+'COMISARIATO CON INSS'!T9 -> M | X14: =+'COMISARIATO CON INSS'!U9 -> M | Y14: =+'COMISARIATO CON INSS'!V9 -> J | Z14: =+'COMISARIATO CON INSS'!W9 -> V | AA14: =+'COMISARIATO CON INSS'!X9 -> S | AB14: =+'COMISARIATO CON INSS'!Y9 -> D
A15: 1 | B15: =+F15 -> 313.19881 | C15: 256.55 | D15: =VLOOKUP(A11,'Cambio del dia'!F7:G38,2,1) -> 36.6243 | E15: =+D15*C15 -> 9395.9642 | F15: =+E15/30 -> 313.19881 | G15: HENRY RIZO HERNANDEZ | H15: 147.16 | I15: M | J15: PLANILLA Y BODEGAS | K15: 0 | L15: 0 | M15: 0 | N15: 0 | O15: 0 | P15: 0 | Q15: 0 | R15: =COUNTIF(K15:Q15,147.16) -> 0 | S15: =COUNTIF(R15,6) -> 0 | T15: 0 | U15: 0 | V15: 0 | W15: 0 | X15: 0 | Y15: 0 | Z15: 0 | AA15: 0 | AB15: 0 | AC15: =COUNTIF(T15:Z15,147.16) -> 0 | AD15: =COUNTIF(AC15,6) -> 0 | AE15: =+AD15+S15 -> 0 | AF15: =COUNTIF(K15:AD15,147.16) -> 0 | AG15: =+AF15+AE15+AJ15+AH15 -> 0 | AH15: 0 | AI15: 0 | AJ15: =+W15+N15 -> 0 | AK15: =+AB15+Y15+X15+V15+U15+T15+Q15+P15+O15+M15+L15+K15+AA15+Z15 -> 0 | AL15: 147.16 | AM15: =H15*AD15 -> 0 | AN15: =+AL15*S15+AM15*AD15 -> 0 | AO15: =+H15 -> 147.16 | AP15: =+H15/8 -> 18.395 | AQ15: =+AO15*AJ15 -> 0 | AR15: =+AP15*AI15 -> 0 | AS15: =+AH15*H15 -> 0 | AT15: =+AL15*N15+AM15*W15 -> 0 | AU15: =+AG15 -> 0 | AV15: =+B15 -> 313.19881 | AW15: 124 | AX15: 0.857142 | AY15: =AU15*AV15 -> 0 | AZ15: =+AY15-BI15 -> 0 | BA15: =AU15*AW15*AX15 -> 0 | BB15: 0.8333 | BC15: =+AN15+AK15 -> 0 | BD15: =+BJ15-BC15 -> 0 | BE15: =+AY15 -> 0 | BF15: 0 | BG15: =BK15*5% -> 0 | BH15: =+BE15/12 -> 0 | BI15: =+BH15 -> 0 | BJ15: =BE15 -> 0 | BK15: =+BJ15-BI15 -> 0 | BL15: 5 | BM15: 0 | BN15: =+BJ15-BM15 -> 0 | BO15: 0 | BP15: =+BN15+BO15+AR15-BG15 -> 0 | BQ15: =+A15 -> 1
I16: =COUNTIF(I15,"F") -> 0
BB18: 3570.2
T26: _______________________________________________ | AT26: ____________________________________
G27: ELABORADO | U27: REVISADO | AT27: AUTORIZADO
G28: Henry Rizo H | U28: LIC. PASTOR CHAVARRIA HERRERA | AT28: LIC. OSMAN GUTIERREZ

Sheet ADMON
A2: AGRICOLA SANTA ISABEL
A3: JINOTEGA NICARAGUA
A4: PLANILLA DE SALARIO QUINCENAL PERSONAL ADMINISTRATIVO
A5: QUINCENA DEL 16 AL 30 DE ABRIL - 2026
A6: 15
A7: No | B7: INSS | C7: NUMERO CEDULA | D7: NOMBRES Y APELLIDOS | E7: GENERO | F7: CARGO | G7: salario en dolares | H7: cambio del dia | I7: SALARIO BASICO | J7: SALARIO MENSUAL | K7: I N G R E S O S | T7: RETENCIONES | X7: TOTAL DEVENGADO | Y7: ALIMENTACION | Z7: FINCA | AA7: NETO A PAGAR | AB7: COMISARIATO | AC7: TOTAL A PAGAR | AD7: FIRMAS | AE7: INSS PATRONAL | AF7: INATEC 2% | AG7: VACACIONES | AH7: 13vo mes | AI7: TOTAL GASTOS NOMINAS
K8: SALARIO QUINCENAL | L8: DIAS LABORADOS | M8: TOTAL SUBCIDIO | N8: SUBCIDIO POR DIA | O8: DIAS SUBCICIO | P8: TOTAL BASICO | Q8: VACACIONES | R8: AGUINALDO | S8: TOTAL INGRESO | T8: INSS LABORAL | U8: IR | W8: TOTAL RETENCION
D10: ADMINISTRACION FINCA
A11: 1 | B11: 26875888 | C11: 241-051289-0002Y | D11: DEXIS MILENA PICADO GARCIA | E11: F | F11: SECRETARIA | G11: 227.47 | H11: 36.6243 | I11: =+K11/15 -> 277.69765 | J11: =+G11*H11 -> 8330.9295 | K11: =(J11/30)*L11 -> 4165.4648 | L11: 15 | M11: =+O11*N11 -> 0 | N11: =+I11*60% -> 166.61859 | O11: 0 | P11: =+K11-M11 -> 4165.4648 | S11: =+P11 -> 4165.4648 | T11: =IF(B11="",0,(P11*7%)) -> 291.58253 | W11: =+T11+U11+V11 -> 291.58253 | X11: =+P11-W11 -> 3873.8822 | Z11: 500 | AA11: =+X11-Z11 -> 3373.8822 | AB11: 500 | AC11: =+X11-Z11-AB11 -> 2873.8822 | AD11: =+A11 -> 1 | AE11: =+P11*21.5% -> 895.57492 | AF11: =IF(T11>0,P11*2%,0) -> 83.309295 | AG11: =+K11/12 -> 347.12206 | AH11: =+AG11 -> 347.12206 | AI11: =SUM(P11,AE11:AF11)+AG11+AH11 -> 5838.5931
A12: 2 | B12: 40238649 | C12: 241-050476-0008Y | D12: GISELLE WALESKA ESPINAL SALGUERA | E12: F | F12: CERTIFICACION | G12: 350 | H12: 36.6243 | I12: =+K12/15 -> 427.2835 | J12: =+G12*H12 -> 12818.505 | K12: =(J12/30)*L12 -> 6409.2525 | L12: 15 | M12: =+O12*N12 -> 0 | N12: =+I12*60% -> 256.3701 | O12: 0 | P12: =+K12-M12 -> 6409.2525 | S12: =+P12 -> 6409.2525 | T12: =IF(B12="",0,(P12*7%)) -> 448.64767 | U12: =+((((P12-T12)*24)-100000)*15%/24) -> 269.09072 | V12: 0 | W12: =+T12+U12+V12 -> 717.7384 | X12: =+P12-W12 -> 5691.5141 | Z12: 1000 | AA12: =+X12-Z12 -> 4691.5141 | AC12: =X12-Z12 -> 4691.5141 | AD12: =+A12 -> 2 | AE12: =+P12*21.5% -> 1377.9893 | AF12: =IF(T12>0,P12*2%,0) -> 128.18505 | AG12: =+K12/12 -> 534.10438 | AH12: =+AG12 -> 534.10438 | AI12: =SUM(P12,AE12:AF12)+AG12+AH12 -> 8983.6356
A13: 3 | B13: 17814405 | C13: 001-080763-0045M | D13: MANUEL DE JESUS HUETES | E13: M | F13: JEFE DE TRANSPORTE | G13: 245.73 | H13: 36.6243 | I13: =+K13/15 -> 339.98826 | J13: =+H13*G13 -> 8999.6892 | K13: =(J13/30)*L13 -> 5099.8239 | L13: 17 | M13: =+O13*N13 -> 0 | N13: =+I13*60% -> 203.99296 | O13: 0 | P13: =+K13 -> 5099.8239 | S13: =+P13 -> 5099.8239 | T13: =IF(B13="",0,(P13*7%)) -> 356.98767 | W13: =+T13+U13+V13 -> 356.98767 | X13: =+P13-W13 -> 4742.8362 | AA13: =+X13-Z13 -> 4742.8362 | AC13: =X13-Z13 -> 4742.8362 | AD13: =+A13 -> 3 | AE13: =+P13*21.5% -> 1096.4621 | AF13: =IF(T13>0,P13*2%,0) -> 101.99648 | AG13: =+K13/12 -> 424.98533 | AH13: =+AG13 -> 424.98533 | AI13: =SUM(P13,AE13:AF13)+AG13+AH13 -> 7148.2532
A14: 4 | B14: 38675494 | C14: 241-060492-0003J | D14: SANDRO OSMANY GUITIERREZ | E14: M | F14: ADMINISTRADOR | G14: 167 | H14: 36.6243 | I14: =+K14/15 -> 203.87533 | J14: 6116.26 | K14: =(J14/30)*L14 -> 3058.13 | L14: 15 | M14: =+O14*N14 -> 0 | N14: =+I14*60% -> 122.3252 | O14: 0 | P14: =+K14-Q14-R14 -> 2548.4417 | Q14: =+K14/12 -> 254.84417 | R14: =+K14/12 -> 254.84417 | S14: =P14+Q14+R14 -> 3058.13 | T14: =+(P14+Q14)*7% -> 196.23001 | W14: =+T14+U14+V14 -> 196.23001 | X14: =S14-T14 -> 2861.9 | Z14: 0 | AA14: =+X14-Z14 -> 2861.9 | AC14: =X14-Z14 -> 2861.9 | AD14: =+A14 -> 4 | AE14: =+P14*21.5% -> 547.91496 | AF14: =IF(T14>0,P14*2%,0) -> 50.968833 | AG14: =+K14/12 -> 254.84417 | AH14: =+AG14 -> 254.84417 | AI14: =SUM(P14,AE14:AF14)+AG14+AH14 -> 3657.0138
A15: 5 | B15: 12762134 | C15: 241-090775-0014S | D15: IVAN OROZCO OSEJO | E15: M | F15: AUXILIAR CONTABLE | G15: 167 | H15: 36.6243 | I15: =+K15/15 -> 350 | J15: 10500 | K15: =(J15/30)*L15 -> 5250 | L15: 15 | M15: =+O15*N15 -> 0 | N15: =+I15*60% -> 210 | O15: 0 | P15: =+K15-Q15-R15 -> 5250 | Q15: 0 | R15: 0 | S15: =P15+Q15+R15 -> 5250 | T15: =+(P15+Q15)*7% -> 367.5 | V15: 0 | W15: =+T15+U15+V15 -> 367.5 | X15: =+S15-W15 -> 4882.5 | Z15: 0 | AA15: =+X15-Z15 -> 4882.5 | AB15: 308 | AC15: =+AA15-AB15 -> 4574.5 | AD15: =+A15 -> 5 | AE15: =+P15*21.5% -> 1128.75 | AF15: =IF(T15>0,P15*2%,0) -> 105 | AG15: =+K15/12 -> 437.5 | AH15: =+AG15 -> 437.5 | AI15: =SUM(P15,AE15:AF15)+AG15+AH15 -> 7358.75
A16: 5 | D16: JUBER ELUIDTH | E16: M | F16: RESP DE FINCA | G16: 167 | H16: 36.6243 | I16: =+K16/15 -> 833.33333 | J16: 25000 | K16: =(J16/30)*L16 -> 12500 | L16: 15 | M16: =+O16*N16 -> 0 | N16: =+I16*60% -> 500 | O16: 0 | P16: =+K16-Q16-R16 -> 12500 | Q16: 0 | R16: 0 | S16: =P16+Q16+R16 -> 12500 | T16: =+(P16+Q16)*7% -> 875 | U16: =+((((P16-T16)*24)-100000)*15%/24) -> 1118.75 | V16: 0 | W16: =+T16+U16+V16 -> 1993.75 | X16: =+S16-W16 -> 10506.25 | Z16: 0 | AA16: =+X16-Z16 -> 10506.25 | AB16: 0 | AC16: =+AA16-AB16 -> 10506.25 | AD16: =+A16 -> 5 | AE16: =+P16*21.5% -> 2687.5 | AF16: =IF(T16>0,P16*2%,0) -> 250 | AG16: =+K16/12 -> 1041.6667 | AH16: =+AG16 -> 1041.6667 | AI16: =SUM(P16,AE16:AF16)+AG16+AH16 -> 17520.833
A17: SUB TOTAL | G17: =SUM(G11:G16) -> 1324.2 | H17: =SUM(H11:H16) -> 219.7458 | J17: =SUM(J11:J16) -> 71765.384 | K17: =SUM(K11:K16) -> 36482.671 | L17: =SUM(L11:L16) -> 92 | P17: =SUM(P11:P16) -> 35972.983 | Q17: =SUM(Q11:Q16) -> 254.84417 | R17: =SUM(R11:R16) -> 254.84417 | S17: =SUM(S11:S16) -> 36482.671 | T17: =SUM(T11:T16) -> 2535.9479 | U17: =SUM(U11:U16) -> 1387.8407 | V17: =SUM(V11:V16) -> 0 | W17: =SUM(W11:W16) -> 3923.7886 | ... Z17: =SUM(Z11:Z16) -> 1500 | AA17: =+X17-Z17 -> 31058.883 | AB17: =SUM(AB11:AB16) -> 808 | AC17: =SUM(AC11:AC16) -> 30250.883 | AE17: =SUM(AE11:AE16) -> 7734.1913 | AF17: =SUM(AF11:AF16) -> 719.45966 | AG17: =SUM(AG11:AG16) -> 3040.2226 | AH17: =SUM(AH11:AH16) -> 3040.2226 | AI17: =SUM(AI11:AI16) -> 50507.079
D18: AREA TECNICA
A19: 6 | B19: 35126559 | C19: 241-241192-0000Q | D19: KEYLING JOHANA PEREZ MARTINEZ | E19: F | F19: ATENCION AL CLIENTE Y CAJA | G19: 204.782 | H19: 36.6243 | J19: =+H19*G19 -> 7499.9974 | K19: =(J19/30)*L19 -> 3749.9987 | L19: 15 | P19: =+K19-Q19-R19 -> 3749.9987 | Q19: 0 | R19: 0 | S19: =P19+Q19+R19 -> 3749.9987 | T19: =+(P19+Q19)*5% -> 187.49994 | W19: =+T19+U19+V19 -> 187.49994 | X19: =S19-T19 -> 3562.4988 | Z19: 0 | AA19: =+X19-Z19 -> 3562.4988 | AB19: 0 | AC19: =+X19-Z19-AB19 -> 3562.4988 | AD19: =+A19 -> 6 | AE19: =+P19*21.5% -> 806.24972 | AF19: =IF(T19>0,P19*2%,0) -> 74.999974 | AG19: =+K19/12 -> 312.49989 | AH19: =+AG19 -> 312.49989 | AI19: =SUM(P19,AE19:AF19)+AG19+AH19 -> 5256.2482
A20: SU TOTAL | J20: =SUM(J19) -> 7499.9974 | K20: =SUM(K19) -> 3749.9987 | L20: =SUM(L19) -> 15 | P20: =SUM(P19) -> 3749.9987 | Q20: =SUM(Q19) -> 0 | R20: =SUM(R19) -> 0 | S20: =SUM(S19) -> 3749.9987 | T20: =SUM(T19) -> 187.49994 | U20: =SUM(U19) -> 0 | V20: =SUM(V19) -> 0 | W20: =SUM(W19) -> 187.49994 | ... Z20: =SUM(Z19) -> 0 | AA20: =+X20-Z20 -> 3562.4988 | AB20: =+AB19 -> 0 | AC20: =SUM(AC19) -> 3562.4988 | AE20: =SUM(AE19) -> 806.24972 | AF20: =SUM(AF19) -> 74.999974 | AG20: =SUM(AG19) -> 312.49989 | AH20: =SUM(AH19) -> 312.49989 | AI20: =SUM(AI19) -> 5256.2482
A21: TOTALES | J21: =+J17+J20 -> 79265.381 | K21: =+K17+K20 -> 40232.67 | L21: =+L17+L20 -> 107 | P21: =+P17+P20 -> 39722.982 | Q21: =+Q17+Q20 -> 254.84417 | R21: =+R17+R20 -> 254.84417 | S21: =+S17+S20 -> 40232.67 | T21: =+T17+T20 -> 2723.4478 | U21: =+U17+U20 -> 1387.8407 | V21: =+V17+V20 -> 0 | W21: =+W17+W20 -> 4111.2885 | ... Z21: =+Z17+Z20 -> 1500 | AA21: =+X21-Z21 -> 34621.381 | AB21: =+AB17+AB20 -> 808 | AC21: =+X21-Z21-AB21 -> 33813.381 | AD21: =+TECNICOS!Z15 -> "EL SEÑOR ES MI PASTOR, NADA ME FALTARA" | AE21: =+AE17+AE20 -> 8540.441 | AF21: =+AF17+AF20 -> 794.45963 | AG21: =+AG17+AG20 -> 3352.7225 | AH21: =+AH17+AH20 -> 3352.7225 | AI21: =+AI17+AI20 -> 55763.327
H23: =500*35.6348 -> 17817.4
C29: ELABORADO POR: | K29: REVISADO POR: | AC29: AUTORIZADO POR:
C30: Jose Martin Conrrado | K30: IVAN OROZCO OSEJO | AC30: LIC: OSMAN G GUTIERREZ MORENO

Sheet Hoja2

Sheet ADMON COM. 
A2: AGRICOLA SANTA ISABEL
A3: JINOTEGA NICARAGUA
A4: PLANILLA DE SALARIO QUINCENAL PERSONAL ADMINISTRATIVO COMERCIAL
A5: =+ADMON!A5 -> QUINCENA DEL 16 AL 30 DE ABRIL - 2026
A6: 15
A7: No | B7: INSS | C7: NUMERO CEDULA | D7: NOMBRES Y APELLIDOS | E7: GENERO | F7: CARGO | G7: salario en dolares | H7: cambio del dia | I7: SALARIO MENSUAL | J7: I N G R E S O S | P7: RETENCIONES | T7: TOTAL DEVENGADO | U7: ALIMENTACION | V7: FINCA | W7: TOTAL A PAGAR | X7: FIRMAS | Y7: INSS PATRONAL | Z7: INATEC 2% | AA7: VACACIONES | AB7: 13vo mes | AC7: TOTAL GASTOS NOMINAS
J8: SALARIO QUINCENAL | K8: DIAS LABORADOS | L8: TOTAL BASICO | M8: VACACIONES | N8: AGUINALDO | O8: TOTAL INGRESO | P8: INSS LABORAL | Q8: IR | R8: ABONO RESTAMOS | S8: TOTAL RETENCION
A10: AREA TECNICA
A11: 1 | B11: 8069333 | C11: 001-040170-0013R | D11: JOSE MANUEL MORAGA FLORES | E11: M | F11: JEFE COMERCIAL | G11: 700 | H11: =LOOKUP(A6,'Cambio del dia'!F1:G38) -> 36.6243 | I11: =+H11*G11 -> 25637.01 | J11: =(I11/30)*K11 -> 12818.505 | K11: 15 | L11: =+J11 -> 12818.505 | O11: =+L11 -> 12818.505 | P11: =IF(B11="",0,(L11*7%)) -> 897.29535 | Q11: =+((((L11-P11)*24)-100000)*15%/24) -> 1163.1814 | R11: 0 | S11: =+P11+Q11+R11 -> 2060.4768 | T11: =L11-P11-Q11 -> 10758.028 | V11: 0 | W11: =+U11+T11-V11 -> 10758.028 | X11: =+A11 -> 1 | Y11: =+L11*21.5% -> 2755.9786 | Z11: =IF(P11>0,L11*2%,0) -> 256.3701 | AA11: =+J11/12 -> 1068.2088 | AB11: =+AA11 -> 1068.2088 | AC11: =SUM(L11,Y11:Z11)+AA11+AB11 -> 17967.271
A12: 2 | B12: 25093885 | C12: 241-091087-0001E | D12: YANT CARLO FERRUFINO PINEDA | E12: M | F12: ASESOR TECNICO Y FINANCIERO | G12: 350 | H12: 36.6243 | I12: =+H12*G12 -> 12818.505 | J12: =(I12/30)*K12 -> 6409.2525 | K12: 15 | L12: =+J12 -> 6409.2525 | O12: =+L12 -> 6409.2525 | P12: =IF(B12="",0,(L12*7%)) -> 448.64767 | Q12: =+((((L12-P12)*24)-100000)*15%/24) -> 269.09072 | R12: 0 | S12: =+P12+Q12+R12 -> 717.7384 | T12: =+L12-S12 -> 5691.5141 | V12: 0 | W12: =+U12+T12-V12 -> 5691.5141 | X12: =+A12 -> 2 | Y12: =+L12*21.5% -> 1377.9893 | Z12: =IF(P12>0,L12*2%,0) -> 128.18505 | AA12: =+J12/12 -> 534.10438 | AB12: =+AA12 -> 534.10438 | AC12: =SUM(L12,Y12:Z12)+AA12+AB12 -> 8983.6356
A13: 3 | B13: 5357574 | C13: 241-300565-0007T | D13: LUIS FERNANDO PALACIOS RIOS | E13: M | F13: ASESOR TECNICO Y FINANCIERO | G13: 350 | H13: 36.6243 | I13: =+H13*G13 -> 12818.505 | J13: =(I13/30)*K13 -> 0 | K13: 0 | L13: =+J13 -> 0 | O13: =+L13 -> 0 | P13: =IF(B13="",0,(L13*7%)) -> 0 | Q13: =+((((L13-P13)*24)-100000)*15%/24) -> -625 | R13: 0 | S13: =+P13+Q13+R13 -> -625 | T13: 0 | V13: 0 | W13: =+U13+T13-V13 -> 0 | X13: =+A13 -> 3 | Y13: =+L13*21.5% -> 0 | Z13: =IF(P13>0,L13*2%,0) -> 0 | AA13: =+J13/12 -> 0 | AB13: =+AA13 -> 0 | AC13: =SUM(L13,Y13:Z13)+AA13+AB13 -> 0
A14: 4 | B14: 21371240 | C14: 001-210878-0075X | D14: JACKS HERRY TORRES PEREZ | E14: M | F14: ASESOR TECNICO Y FINANCIERO | G14: 350 | H14: 36.6243 | I14: =+H14*G14 -> 12818.505 | J14: =(I14/30)*K14 -> 6409.2525 | K14: 15 | L14: =+J14 -> 6409.2525 | O14: =+L14 -> 6409.2525 | P14: =IF(B14="",0,(L14*7%)) -> 448.64767 | Q14: =+((((L14-P14)*24)-100000)*15%/24) -> 269.09072 | R14: 0 | S14: =+P14+Q14+R14 -> 717.7384 | T14: =+L14-S14 -> 5691.5141 | V14: 0 | W14: =+U14+T14-V14 -> 5691.5141 | X14: =+A14 -> 4 | Y14: =+L14*21.5% -> 1377.9893 | Z14: =IF(P14>0,L14*2%,0) -> 128.18505 | AA14: =+J14/12 -> 534.10438 | AB14: =+AA14 -> 534.10438 | AC14: =SUM(L14,Y14:Z14)+AA14+AB14 -> 8983.6356
A15: 5 | B15: 19144283 | C15: 241-210680-0011D | D15: CESAR AUGUSTO ZEAS | E15: M | F15: ASESOR TECNICO Y FINANCIERO | G15: 350 | H15: 36.6243 | I15: =+H15*G15 -> 12818.505 | J15: =(I15/30)*K15 -> 6409.2525 | K15: 15 | L15: =+J15 -> 6409.2525 | O15: =+L15 -> 6409.2525 | P15: =IF(B15="",0,(L15*7%)) -> 448.64767 | Q15: =+((((L15-P15)*24)-100000)*15%/24) -> 269.09072 | R15: 0 | S15: =+P15+Q15+R15 -> 717.7384 | T15: =+L15-S15 -> 5691.5141 | V15: 0 | W15: =+U15+T15-V15 -> 5691.5141 | X15: =+A15 -> 5 | Y15: =+L15*21.5% -> 1377.9893 | Z15: =IF(P15>0,L15*2%,0) -> 128.18505 | AA15: =+J15/12 -> 534.10438 | AB15: =+AA15 -> 534.10438 | AC15: =SUM(L15,Y15:Z15)+AA15+AB15 -> 8983.6356
A16: SUB TOTAL | I16: =SUM(I11:I15) -> 76911.03 | J16: =SUM(J11:J15) -> 32046.262 | K16: =SUM(K11:K15) -> 60 | L16: =SUM(L11:L15) -> 32046.262 | M16: =SUM(M11:M15) -> 0 | N16: =SUM(N11:N15) -> 0 | O16: =SUM(O11:O15) -> 32046.262 | P16: =SUM(P11:P15) -> 2243.2384 | ... W16: =SUM(W11:W15) -> 27832.571 | Y16: =SUM(Y11:Y15) -> 6889.9464 | Z16: =SUM(Z11:Z15) -> 640.92525 | AA16: =SUM(AA11:AA15) -> 2670.5219 | AB16: =SUM(AB11:AB15) -> 2670.5219 | AC16: =SUM(AC11:AC15) -> 44918.178
A17: ADMINISTRACION
A18: 6 | B18: 16167647 | C18: 241-301272-0001U | D18: ARMANDO JOSE IGLESIAS | E18: M | F18: JEFE INDUSTRIAL | G18: 500 | H18: =LOOKUP(A6,'Cambio del dia'!F2:G38) -> 36.6243 | I18: =+H18*G18 -> 18312.15 | J18: =(I18/30)*K18 -> 9156.075 | K18: 15 | L18: =+J18 -> 9156.075 | O18: =+L18 -> 9156.075 | P18: =IF(B18="",0,(L18*7%)) -> 640.92525 | Q18: =+((((L18-P18)*24)-100000)*15%/24) -> 652.27246 | R18: 0 | S18: =+P18+Q18+R18 -> 1293.1977 | T18: =L18-P18-Q18 -> 7862.8773 | V18: 0 | W18: =+U18+T18-V18 -> 7862.8773 | X18: =+A18 -> 6 | Y18: =+L18*21.5% -> 1968.5561 | Z18: =IF(P18>0,L18*2%,0) -> 183.1215 | AA18: =+J18/12 -> 763.00625 | AB18: =+AA18 -> 763.00625 | AC18: =SUM(L18,Y18:Z18)+AA18+AB18 -> 12833.765
A19: 7 | B19: 14049864 | C19: 241-050475-0001W | D19: VICENTE ALBERTO GADEA | E19: M | F19: JEFE DE PRODUCCION | G19: 500 | H19: 36.6243 | I19: =+H19*G19 -> 18312.15 | J19: =(I19/30)*K19 -> 9156.075 | K19: 15 | L19: =+J19 -> 9156.075 | O19: =+L19 -> 9156.075 | P19: =IF(B19="",0,(L19*7%)) -> 640.92525 | Q19: =+((((L19-P19)*24)-100000)*15%/24) -> 652.27246 | R19: 0 | S19: =+P19+Q19+R19 -> 1293.1977 | T19: =L19-P19-Q19 -> 7862.8773 | V19: 0 | W19: =+U19+T19-V19 -> 7862.8773 | X19: =+A19 -> 7 | Y19: =+L19*21.5% -> 1968.5561 | Z19: =IF(P19>0,L19*2%,0) -> 183.1215 | AA19: =+J19/12 -> 763.00625 | AB19: =+AA19 -> 763.00625 | AC19: =SUM(L19,Y19:Z19)+AA19+AB19 -> 12833.765
A20: 8 | B20: 9034666 | C20: 241-260465-0010G | D20: NELLY DEL CARMEN SOBALVARRO THOMAS | E20: F | F20: AUXILIAR CONTABLE | G20: 298.9818 | H20: 36.6243 | I20: =+H20*G20 -> 10949.999 | J20: =(I20/30)*K20 -> 0 | K20: 0 | L20: =+J20 -> 0 | O20: =+L20 -> 0 | P20: =IF(B20="",0,(L20*7%)) -> 0 | Q20: 0 | R20: 0 | S20: =+P20+Q20+R20 -> 0 | T20: =+L20-S20 -> 0 | V20: 0 | W20: =+U20+T20-V20 -> 0 | X20: =+A20 -> 8 | Y20: =+L20*21.5% -> 0 | Z20: =IF(P20>0,L20*2%,0) -> 0 | AA20: =+J20/12 -> 0 | AB20: =+AA20 -> 0 | AC20: =SUM(L20,Y20:Z20)+AA20+AB20 -> 0
A21: 9 | B21: 26875888 | C21: 003-020172-0001X | D21: ARMANDO GUIDO GONZALEZ | E21: M | F21: AUXILIAR CONTABLE ACOPIO | G21: 298.9818 | H21: 36.6243 | I21: =+H21*G21 -> 10949.999 | J21: =(I21/30)*K21 -> 5474.9996 | K21: 15 | L21: =+J21 -> 5474.9996 | O21: =+L21 -> 5474.9996 | P21: =IF(B21="",0,(L21*7%)) -> 383.24997 | Q21: =+((((L21-P21)*24)-100000)*15%/24) -> 138.76244 | R21: 0 | S21: =+P21+Q21+R21 -> 522.01241 | T21: =+L21-S21 -> 4952.9872 | V21: 500 | W21: =+U21+T21-V21 -> 4452.9872 | X21: =+A21 -> 9 | Y21: =+L21*21.5% -> 1177.1249 | Z21: =IF(P21>0,L21*2%,0) -> 109.49999 | AA21: =+J21/12 -> 456.24996 | AB21: =+AA21 -> 456.24996 | AC21: =SUM(L21,Y21:Z21)+AA21+AB21 -> 7674.1244
A22: SUB TOTAL | I22: =SUM(I18:I21) -> 58524.298 | J22: =SUM(J18:J21) -> 23787.15 | K22: =SUM(K18:K21) -> 45 | L22: =SUM(L18:L21) -> 23787.15 | M22: =SUM(M18:M21) -> 0 | N22: =SUM(N18:N21) -> 0 | O22: =SUM(O18:O21) -> 23787.15 | P22: =SUM(P18:P21) -> 1665.1005 | ... W22: =SUM(W18:W21) -> 20178.742 | Y22: =SUM(Y18:Y21) -> 5114.2372 | Z22: =SUM(Z18:Z21) -> 475.74299 | AA22: =SUM(AA18:AA21) -> 1982.2625 | AB22: =SUM(AB18:AB21) -> 1982.2625 | AC22: =SUM(AC18:AC21) -> 33341.655
A23: ACOPIO ABISINIA | D23: ACOPIO ABISINIA
A24: 10 | B24: 7305067 | C24: 241-140864-0000B | D24: MARIA HULDA GARCIA RIVAS | E24: F | F24: ATENCION AL CLIENTE | G24: 298.9818 | H24: 36.6243 | I24: =+H24*G24 -> 10949.999 | J24: =(I24/30)*K24 -> 5474.9996 | K24: 15 | L24: =+J24 -> 5474.9996 | O24: =+L24 -> 5474.9996 | P24: =IF(B24="",0,(L24*7%)) -> 383.24997 | Q24: =+((((L24-P24)*24)-100000)*15%/24) -> 138.76244 | R24: 0 | S24: =+P24+Q24+R24 -> 522.01241 | T24: =+L24-S24 -> 4952.9872 | V24: 0 | W24: =+U24+T24-V24 -> 4952.9872 | X24: =+A24 -> 10 | Y24: =+L24*21.5% -> 1177.1249 | Z24: =IF(P24>0,L24*2%,0) -> 109.49999 | AA24: =+J24/12 -> 456.24996 | AB24: =+AA24 -> 456.24996 | AC24: =SUM(L24,Y24:Z24)+AA24+AB24 -> 7674.1244
A25: SUB TOTAL | I25: =SUM(I24) -> 10949.999 | J25: =SUM(J24) -> 5474.9996 | K25: =SUM(K24) -> 15 | L25: =SUM(L24) -> 5474.9996 | M25: =SUM(M24) -> 0 | N25: =SUM(N24) -> 0 | O25: =SUM(O24) -> 5474.9996 | P25: =SUM(P24) -> 383.24997 | ... W25: =SUM(W24) -> 4952.9872 | Y25: =SUM(Y24) -> 1177.1249 | Z25: =SUM(Z24) -> 109.49999 | AA25: =SUM(AA24) -> 456.24996 | AB25: =SUM(AB24) -> 456.24996 | AC25: =SUM(AC24) -> 7674.1244
A26: BENEFICIO HUMEDO
A27: 11 | B27: 21389447 | C27: 442-120970-0000R | D27: CESAR AUGUSTO ALEMAN | E27: M | F27: RESPONSABLE BENEFICIO HUMEDO | G27: 298.9818 | H27: 36.6243 | I27: =+H27*G27 -> 10949.999 | J27: 5475 | K27: 15 | L27: 4692.855 | M27: =L27/12 -> 391.07125 | N27: =+L27/12 -> 391.07125 | O27: =+L27++M27+N27 -> 5474.9975 | P27: =IF(B27="",0,(L27*7%)) -> 328.49985 | Q27: =+((((L27-P27)*24)-100000)*15%/24) -> 29.653272 | R27: 0 | S27: =+P27+Q27+R27 -> 358.15312 | T27: =+L27-S27 -> 4334.7019 | V27: 0 | W27: =+U27+T27-V27 -> 4334.7019 | X27: =+A27 -> 11 | Y27: =+L27*21.5% -> 1008.9638 | Z27: =IF(P27>0,L27*2%,0) -> 93.8571 | AA27: =+J27/12 -> 456.25 | AB27: =+AA27 -> 456.25 | AC27: =SUM(L27,Y27:Z27)+AA27+AB27 -> 6708.1759
A28: SUB TOTAL | I28: =SUM(I27) -> 10949.999 | J28: =SUM(J27) -> 5475 | K28: =SUM(K27) -> 15 | L28: =SUM(L27) -> 4692.855 | M28: =SUM(M27) -> 391.07125 | N28: =SUM(N27) -> 391.07125 | O28: =SUM(O27) -> 5474.9975 | P28: =SUM(P27) -> 328.49985 | ... W28: =SUM(W27) -> 4334.7019 | Y28: =SUM(Y27) -> 1008.9638 | Z28: =SUM(Z27) -> 93.8571 | AA28: =SUM(AA27) -> 456.25 | AB28: =SUM(AB27) -> 456.25 | AC28: =SUM(AC27) -> 6708.1759
A29: 15 | B29: 38675494 | C29: 241-060492-0003J | D29: SANDRO OSMANY GUITIERREZ | E29: M | F29: ADMINISTRADOR | G29: 167 | H29: 36.6243 | I29: 6116.26 | J29: =(I29/30)*K29 -> 3058.13 | K29: 15 | L29: =+J29-M29-N29 -> 2548.4417 | M29: =+J29/12 -> 254.84417 | N29: =+J29/12 -> 254.84417 | O29: =L29+M29+N29 -> 3058.13 | P29: =+(L29+M29)*7% -> 196.23001 | S29: =+P29+Q29+R29 -> 196.23001 | T29: =O29-P29 -> 2861.9 | V29: 0 | W29: =O29-P29 -> 2861.9 | X29: =+A29 -> 15 | Y29: =+L29*21.5% -> 547.91496 | Z29: =IF(P29>0,L29*2%,0) -> 50.968833 | AA29: 0 | AB29: 0 | AC29: =SUM(L29,Y29:Z29)+AA29+AB29 -> 3147.3255
A30: TOTALES | I30: =+I16+I22+I25+I28 -> 157335.33 | J30: =+J16+J22+J25+J28 -> 66783.412 | K30: =+K16+K22+K25+K28 -> 135 | L30: =+L16+L22+L25+L28 -> 66001.267 | M30: =+M16+M22+M25+M28 -> 391.07125 | N30: =+N16+N22+N25+N28 -> 391.07125 | O30: =+O16+O22+O25+O28 -> 66783.409 | P30: =+P16+P22+P25+P28 -> 4620.0887 | ... W30: =+W16+W22+W25+W28 -> 57299.001 | X30: =+TECNICOS!Z15 -> "EL SEÑOR ES MI PASTOR, NADA ME FALTARA" | Y30: =+Y16+Y22+Y25+Y28 -> 14190.272 | Z30: =+Z16+Z22+Z25+Z28 -> 1320.0253 | AA30: =+AA16+AA22+AA25+AA28 -> 5565.2843 | AB30: =+AB16+AB22+AB25+AB28 -> 5565.2843 | AC30: =+AC16+AC22+AC25+AC28 -> 92642.133
H32: =500*35.6348 -> 17817.4
C49: ELABORADO POR: | J49: REVISADO POR: | W49: AUTORIZADO POR:
C50: Jose Martin Conrrado | J50: IVAN OROZCO OSEJO | W50: LIC:OSMAN G GUTIERREZ MORENO

Sheet TECNICOS
A2: AGRÍCOLA SANTA ISABEL
A3: PLANILLA DE SALARIO QUINCENAL DE TÉCNICOS DE ACOPIO
A4: =+'ADMON COM. '!A5:AC5 -> QUINCENA DEL 16 AL 30 DE ABRIL - 2026
A5: =+'ADMON COM. '!A6 -> 15
A6: No | B6: INSS | C6: NUMERO DE CEDULA | D6: NOMBRES Y APELLIDOS | E6: GENERO | F6: CARGO | G6: salario en dolares | H6: cambio del dia | I6: SALARIO DIARIO | J6: SALARIO MENSUAL | K6: I N G R E S O S | Q6: RETENCIONES | U6: TOTAL DEVENGADO | V6: COMISARIATO | W6: FINCA | X6: COMISARIATO | Y6: NETO A PAGAR DEVENGADO | Z6: FIRMAS | AA6: VACASIONES | AB6: 13VO MES | AC6: INSS PATRONAL | AD6: INATEC 2% | AE6: VACACIONES | AF6: 13VO MES | AG6: TOTAL GASTOS NOMINAS
K7: SALARIO QUINCENAL | L7: DIAS LABORADOS | M7: total subcidio | N7: subcidio por dia | O7: DIAS SUBSIDIO | P7: TOTAL INGRESOS | Q7: INSS LABORAL | R7: IR | S7: ABONO POR PRESTAMOS | T7: TOTAL RETENCION
A9: 1 | B9: 5357574 | C9: 241-300565-0007T | D9: LUIS FERNANDO PALACIOS RIOS | E9: M | F9: ASESOR TECNICO Y FINANCIERO | G9: 0 | H9: =LOOKUP(A5,'Cambio del dia'!F7:G38) -> 36.6243 | I9: =+K9/L9 -> 0 | J9: =+H9*G9 -> 0 | K9: =(J9/30)*L9 -> 0 | L9: 15 | M9: =+N9*O9 -> 0 | N9: =I9*60% -> 0 | O9: 0 | P9: =+K9-M9 -> 0 | Q9: =IF(B9="",0,(P9*7%)) -> 0 | R9: =IF(AND(P9*24>100000,P9*24<=200000),((((P9-Q9)*24)-100000)*15%)/24,IF(AND(P9*24>100000,P9*24<=200000),(((((P9-Q9)*24)-100000)*15%))/24,)) -> 0 | T9: =+Q9+R9+S9 -> 0 | U9: =-T9+P9 -> 0 | V9: 0 | W9: 0 | Y9: =+P9-T9+V9 -> 0 | AA9: =+J9/30*1.25 -> 0 | AB9: =+J9/30*1.25 -> 0 | AC9: =IF(B9="",0,P9*21.5%) -> 0 | AD9: =IF(Q9>0,P9*2%,0) -> 0 | AE9: =+K9/12 -> 0 | AF9: =+AE9 -> 0 | AG9: =SUM(P9,AC9,AB9,AA9,AD9) -> 0
A10: 2 | B10: 25093885 | C10: 241-091087-0001E | D10: YANT CARLO FERRUFINO PINEDA | E10: M | F10: ASESOR TECNICO Y FINANCIERO | G10: 0 | H10: =LOOKUP(A5,'Cambio del dia'!F7:G38) -> 36.6243 | I10: =+P10/L10 -> 0 | J10: =+H10*G10 -> 0 | K10: =(J10/30)*L10 -> 0 | L10: 15 | M10: =+N10*O10 -> 0 | N10: =I10*60% -> 0 | O10: 0 | P10: =+K10 -> 0 | Q10: =IF(B10="",0,(P10*7%)) -> 0 | R10: =IF(AND(P10*24>100000,P10*24<=200000),((((P10-Q10)*24)-100000)*15%)/24,IF(AND(P10*24>100000,P10*24<=200000),(((((P10-Q10)*24)-100000)*15%))/24,)) -> 0 | T10: =+Q10+R10+S10 -> 0 | U10: =-T10+P10 -> 0 | V10: 0 | W10: 0 | Y10: =+P10-T10+V10-W10 -> 0 | AA10: =+J10/30*1.25 -> 0 | AB10: =+J10/30*1.25 -> 0 | AC10: =IF(B10="",0,P10*21.5%) -> 0 | AD10: =IF(Q10>0,P10*2%,0) -> 0 | AE10: =+K10/12 -> 0 | AF10: =+AE10 -> 0 | AG10: =SUM(P10,AC10,AB10,AA10,AD10) -> 0
A11: 3 | B11: 21371240 | C11: 001-210878-0075X | D11: JACKS HERRY TORRES PEREZ | E11: M | F11: ASESOR TECNICO Y FINANCIERO | G11: 0 | H11: =LOOKUP(A5,'Cambio del dia'!F8:G38) -> 36.6243 | I11: =+P11/L11 -> 0 | J11: =+H11*G11 -> 0 | K11: =(J11/30)*L11 -> 0 | L11: 15 | M11: =+N11*O11 -> 0 | N11: =I11*60% -> 0 | O11: 0 | P11: =+K11 -> 0 | Q11: =IF(B11="",0,(P11*7%)) -> 0 | R11: =IF(AND(P11*24>100000,P11*24<=200000),((((P11-Q11)*24)-100000)*15%)/24,IF(AND(P11*24>100000,P11*24<=200000),(((((P11-Q11)*24)-100000)*15%))/24,)) -> 0 | T11: =+Q11+R11+S11 -> 0 | U11: =-T11+P11 -> 0 | V11: 0 | W11: 0 | Y11: =+P11-T11+V11 -> 0 | AA11: =+J11/30*1.25 -> 0 | AB11: =+J11/30*1.25 -> 0 | AC11: =IF(B11="",0,P11*21.5%) -> 0 | AD11: =IF(Q11>0,P11*2%,0) -> 0 | AE11: =+K11/12 -> 0 | AF11: =+AE11 -> 0 | AG11: =SUM(P11,AC11,AB11,AA11,AD11) -> 0
A12: 4 | B12: 19144283 | C12: 241-210680-0011D | D12: CESAR AUGUSTO ZEAS | E12: M | F12: ASESOR TECNICO Y FINANCIERO | G12: 0 | H12: =LOOKUP(A5,'Cambio del dia'!F7:G38) -> 36.6243 | I12: =+P12/L12 -> 0 | J12: =+H12*G12 -> 0 | K12: =(J12/30)*L12 -> 0 | L12: 15 | M12: =+N12*O12 -> 0 | N12: =I12*60% -> 0 | O12: 0 | P12: =+K12 -> 0 | Q12: =IF(B12="",0,(P12*7%)) -> 0 | R12: =IF(AND(P12*24>100000,P12*24<=200000),((((P12-Q12)*24)-100000)*15%)/24,IF(AND(P12*24>100000,P12*24<=200000),(((((P12-Q12)*24)-100000)*15%))/24,)) -> 0 | T12: =+Q12+R12+S12 -> 0 | U12: =-T12+P12 -> 0 | Y12: =+U12-V12-W12 -> 0 | AA12: =+J12/30*1.25 -> 0 | AB12: =+J12/30*1.25 -> 0 | AC12: =IF(B12="",0,P12*21.5%) -> 0 | AD12: =IF(Q12>0,P12*2%,0) -> 0 | AE12: =+K12/12 -> 0 | AF12: =+AE12 -> 0 | AG12: =SUM(P12,AC12,AB12,AA12,AD12) -> 0
A13: 5 | B13: 35126559 | C13: 241-241192-0000Q | D13: KEYLING JOHANA PEREZ MARTINEZ | E13: F | F13: ATENCION AL CLIENTE Y CAJA | G13: 0 | H13: 0 | I13: 0 | J13: 0 | K13: =(J13/30)*L13 -> 0 | L13: 15 | M13: =+N13*O13 -> 0 | N13: =I13*60% -> 0 | O13: 0 | P13: =+K13 -> 0 | Q13: =IF(B13="",0,(P13*5%)) -> 0 | R13: 0 | T13: =+Q13+R13+S13 -> 0 | U13: =-T13+P13 -> 0 | W13: 0 | Y13: =+P13-T13+V13-W13 -> 0 | AA13: =+J13/30*1.25 -> 0 | AB13: =+J13/30*1.25 -> 0 | AC13: =IF(B13="",0,P13*21.5%) -> 0 | AD13: =IF(Q13>0,P13*2%,0) -> 0 | AE13: =+K13/12 -> 0 | AF13: =+AE13 -> 0 | AG13: =SUM(P13,AC13,AB13,AA13,AD13) -> 0
A14: 6 | B14: 8069333 | C14: 001-040170-0013R | D14: JOSE MANUEL MORAGA | E14: M | F14: COORDINADOR DE ACOPIOS Y FINANZAS | G14: 0 | H14: =LOOKUP(A5,'Cambio del dia'!F7:G38) -> 36.6243 | I14: =+P14/L14 -> 0 | J14: =+H14*G14 -> 0 | K14: =(J14/30)*L14 -> 0 | L14: 15 | M14: =+N14*O14 -> 0 | N14: =I14*60% -> 0 | O14: 0 | P14: =+K14 -> 0 | Q14: =IF(B14="",0,(P14*7%)) -> 0 | R14: =IF(AND(P14*24>100000,P14*24<=200000),((((P14-Q14)*24)-100000)*15%)/24,IF(AND(P14*24>100000,P14*24<=200000),(((((P14-Q14)*24)-100000)*15%))/24,)) -> 0 | T14: =+Q14+R14+S14 -> 0 | U14: =-T14+P14 -> 0 | W14: 0 | Y14: =+P14-T14-V14-W14 -> 0 | AA14: =+J14/30*1.25 -> 0 | AB14: =+J14/30*1.25 -> 0 | AC14: =IF(B14="",0,P14*21.5%) -> 0 | AD14: =IF(Q14>0,P14*2%,0) -> 0 | AE14: =+K14/12 -> 0 | AF14: =+AE14 -> 0 | AG14: =SUM(P14,AC14,AB14,AA14,AD14) -> 0
A15: TOTALES | G15: =SUM(G9:G12) -> 0 | I15: =SUM(I9:I14) -> 0 | J15: =SUM(J9:J14) -> 0 | K15: =SUM(K9:K14) -> 0 | L15: =SUM(L9:L14) -> 90 | M15: =SUM(M9:M14) -> 0 | N15: =SUM(N9:N14) -> 0 | O15: =SUM(O9:O14) -> 0 | P15: =SUM(P9:P14) -> 0 | ... W15: =SUM(W9:W14) -> 0 | X15: =SUM(X9:X12) -> 0 | Y15: =SUM(Y9:Y14) -> 0 | Z15: "EL SEÑOR ES MI PASTOR, NADA ME FALTARA" | AA15: =SUM(AA9:AA10) -> 0 | AB15: =SUM(AB9:AB10) -> 0 | AC15: =SUM(AC9:AC14) -> 0 | AD15: =SUM(AD9:AD14) -> 0 | AE15: =SUM(AE9:AE14) -> 0 | AF15: =SUM(AF9:AF14) -> 0 | AG15: =SUM(AG9:AG14) -> 0
C23: ELABORADO POR: | L23: REVISADO POR: | Y23: AUTORIZADO POR:
C24: =+'ADMON COM. '!C50:F50 -> Jose Martin Conrrado | L24: Ivan Orozco Osejo | Y24: Lic. Osman Gregorio Gutiérrez Moreno

Sheet FINANCIAMIENTO INSS
A2: PLANILLA ACOPIO YEMIN DAVID GUTIERREZ
A3: PLANILLA DE SALARIO QUINCENAL
A4: =+TECNICOS!A4 -> QUINCENA DEL 16 AL 30 DE ABRIL - 2026
A8: No | B8: INSS | C8: NUMERO DE CEDULA | D8: NOMBRES Y APELLIDOS | E8: GENERO | F8: CARGO | G8: salario en dolares | H8: cambio del dia | I8: SALARIO DIARIO | J8: SALARIO MENSUAL | K8: I N G R E S O S | S8: RETENCIONES | Y8: TOTAL | Z8: FINCA | AA8: COMISARIATO | AB8: SALARIO DEVENGADO | AC8: FIRMAS | AF8: INSS PATRONAL | AG8: VACACIONES | AH8: 13VO MES | AI8: INATEC 2% | AJ8: TOTAL GASTOS NOMINAS
K9: SALARIO QUINCENAL | L9: DIAS LABORADOS | M9: total subcidio | N9: subcidio por dia | O9: DIAS SUBSIDIO | P9: TOTAL BASICO | Q9: VACACIONES | R9: 13VO MES | S9: TOTAL | U9: INSS | V9: IR | W9: ABONO POR PRESTAMOS | X9: TOTAL RETENCION
A11: 1 | B11: 17155823 | C11: 241-151294-0004V | D11: KEYLIN JOHANA PEREZ MARTINEZ | E11: F | F11: CAJERA | I11: 250 | J11: =I11*30 -> 7500 | K11: =(J11/30)*L11 -> 0 | L11: 0 | M11: =+N11*O11 -> 0 | N11: =I11*60% -> 150 | O11: 0 | P11: =+K11-Q11-R11 -> 0 | Q11: 0 | R11: 0 | S11: =+P11 -> 0 | T11: =P11+Q11 -> 0 | U11: =+T11*5% -> 0 | X11: =U11 -> 0 | Y11: =-X11+P11+Q11+R11 -> 0 | Z11: 0 | AA11: 0 | AB11: =Y11-Z11-AA11 -> 0 | AD11: 0.155 | AE11: =+S11-R11 -> 0 | AF11: =AD11*S11 -> 0 | AG11: =+K11/12 -> 0 | AH11: =+K11/12 -> 0 | AI11: =0.02*AB11 -> 0 | AJ11: =AB11+AF11+AI11+AG11+AH11 -> 0
A12: TOTALES | G12: =SUM(#REF!) -> #REF! | I12: =SUM(I11:I11) -> 250 | J12: =SUM(J11:J11) -> 7500 | K12: =SUM(K11:K11) -> 0 | L12: 15 | M12: =SUM(M11:M11) -> 0 | N12: =SUM(N11:N11) -> 150 | O12: =SUM(O11:O11) -> 0 | P12: =SUM(P11:P11) -> 0 | Q12: =SUM(Q11:Q11) -> 0 | R12: =SUM(R11:R11) -> 0 | S12: =SUM(S11:S11) -> 0 | T12: =SUM(T11:T11) -> 0 | ... AA12: =SUM(AA11:AA11) -> 0 | AB12: =Y12-Z12-AA12 -> 0 | AC12: "EL SEÑOR ES MI PASTOR, NADA ME FALTARA" | AD12: =SUM(#REF!) -> #REF! | AE12: =SUM(#REF!) -> #REF! | AF12: =SUM(AF11:AF11) -> 0 | AG12: =SUM(AG11:AG11) -> 0 | AH12: =SUM(AH11:AH11) -> 0 | AI12: =SUM(AI11:AI11) -> 0 | AJ12: =SUM(AJ11:AJ11) -> 0
I14: 10
I15: 350 | J15: 35.6948 | K15: =+I15*J15 -> 12493.18
K16: =+I15/J15 -> 9.8053498 | L16: =9.81*30 -> 294.3
C26: ELABORADO POR: | L26: REVISADO POR: | AB26: AUTORIZADO POR:
C27: =+'ADMON COM. '!C50:F50 -> Jose Martin Conrrado | L27: =+'FINCA SIN INSS'!K32:W32 -> 0 | AB27: Lic. Osman Gregorio Gutiérrez Moreno

Sheet Holman
A6: JINOTEGA, NICARAGUA
A7: PLANILLA DE SALARIO QUINCENAL
A8: =+TECNICOS!A4 -> QUINCENA DEL 16 AL 30 DE ABRIL - 2026
A14: No. | B14: SALARIO | C14: NOMBRES Y APELLIDOS | D14: SALARIO DIARIO | E14: Actividad | F14: 1 | G14: 2 | H14: 3 | I14: 4 | J14: 5 | K14: 6 | L14: 7 | M14: 1 semana | N14: SEPTIMO DIA | O14: 8 | P14: 9 | Q14: 10 | R14: 11 | S14: 12 | T14: 13 | U14: 14 | V14: 15 | W14: 31 | Y14: 2 semana | Z14: SEPTIMO DIA | AA14: SUMA SETIMOS | AB14: SUMA DIAS | AD14: DIAS TRABAJADOS | AE14: FERIADOS/ LIBRES | AF14: HRS EXT | AG14: DOM LAB | AH14: SALARIO BASICO | AK14: SEPTIMO DIA | AL14: COSTE DIA | AM14: COSTE HORA | AN14: DOMINGOS TRABAJADOS | AO14: HORAS EXTRAS | AP14: DIAS FERIADOS | AQ14: Extras y/o Dom. Trab | AR14: DIAS | AS14: SALARIO | AT14: DODIGO | AU14: CONSTANTE | AV14: SALARIO 14CENAL | AW14: FORMUAL | AX14: FORMULA | AY14: FORMULA | AZ14: TOTAL | BA14: Adicional | BB14: INGRESO BASICO | BC14: VACASIONES | BD14: 13VO MES | BE14: TOTAL INGRESOS | BI14: SALARIO NETO | BJ14: VIATICO | BK14: NETO A PAGAR | BL14: RECIBIDO CONFORME
F16: S | G16: D | H16: L | I16: M | J16: M | K16: J | L16: V | O16: S | P16: D | Q16: L | R16: M | S16: M | T16: J | U16: V | V16: S | W16: M
A17: 1 | B17: 200 | C17: HOLMAN HIDALGO | D17: 157.46 | E17: ACOPIO | F17: 157.46 | G17: 0 | H17: 157.46 | I17: 157.46 | J17: 157.46 | K17: 157.46 | L17: 157.46 | M17: 7 | N17: =COUNTIF(M17,7) -> 1 | O17: 157.46 | P17: 0 | Q17: 157.46 | R17: 157.46 | S17: 157.46 | T17: 157.46 | U17: 157.46 | V17: 157.46 | W17: 0 | X17: 7 | Y17: 7 | Z17: =COUNTIF(X17,7) -> 1 | AA17: =+Z17+N17 -> 2 | AB17: =+Y17+M17-1 -> 13 | AC17: =+AB17+AA17 -> 15 | AD17: 15 | AE17: =+H17+Q17 -> 314.92 | AF17: 0 | AG17: =+G17+U170 -> 0 | AH17: =+W17+T17+S17+Q17+P17+O17+L17+K17+J17+H17+G17+F17+U17+V17+I17+R17 -> 2046.98 | AI17: 147.16 | AJ17: =D17*Z17 -> 157.46 | AK17: =+AI17*N17+AJ17*Z17 -> 304.62 | AL17: =+D17 -> 157.46 | AM17: =+D17/8 -> 19.6825 | AN17: =+AL17*AG17 -> 0 | AO17: =+AM17*AF17 -> 0 | AP17: =+AE17*D17 -> 49587.303 | AQ17: =+AI17*I17+AJ17*R17 -> 47965.465 | AR17: =+AD17 -> 15 | AS17: =+B17 -> 200 | AT17: 84 | AU17: 0.857142 | AV17: =AR17*AS17 -> 3000 | AW17: =+AV17-BD17 -> 2785.7145 | AX17: =AR17*AT17*AU17 -> 1079.9989 | AY17: 0.857142 | AZ17: =+AK17+AH17 -> 2351.6 | BA17: =+BE17-AZ17 -> 648.397 | BB17: =+AV17*AY17 -> 2571.426 | BC17: =+BB17/12 -> 214.2855 | BD17: =+BC17 -> 214.2855 | BE17: =+BD17+BC17+BB17 -> 2999.997 | BF17: =+BE17-BD17 -> 2785.7115 | BG17: 5 | BH17: 0 | BI17: =+BE17-BH17 -> 2999.997 | BJ17: 0 | BK17: 0 | BL17: =+A17 -> 1
O26: _______________________________________________ | AQ26: ____________________________________
C27: ELABORADO | P27: REVISADO | AQ27: AUTORIZADO
C28: DEMIS CECILIA MONTIEL GONZALEZ. | P28: LIC. PASTOR CHAVARRIA HERRERA | AK28: LIC. OSMAN GUTIERREZ

Sheet FINCA SIN INSS
A2: AGRÍCOLA SANTA ISABEL
A3: PLANILLA DE SALARIO QUINCENAL
A4: =+ADMON!A5 -> QUINCENA DEL 16 AL 30 DE ABRIL - 2026
L6: 6
A7: No | B7: INSS | C7: NUMERO DE CEDULA | D7: NOMBRES Y APELLIDOS | E7: GENERO | F7: CARGO | G7: cambio del dia | H7: SALARIO DIARIO | I7: SALARIO MENSUAL | J7: I N G R E S O S | R7: RETENCIONES | X7: TOTAL | Y7: FINCA | Z7: DEVENGADO | AA7: COMISARIATO | AB7: SALARIO DEVENGADO | AC7: FIRMAS | AD7: =+P8 -> VACACIONES | AE7: =+Q8 -> 13VO MES
J8: SALARIO QUINCENAL | K8: DIAS LABORADOS | L8: total subcidio | M8: subcidio por dia | N8: DIAS SUBSIDIO | O8: TOTAL BASICO | P8: VACACIONES | Q8: 13VO MES | R8: TOTAL | T8: INSS | U8: IR | V8: ABONO POR PRESTAMOS | W8: TOTAL RETENCION
A10: 1 | B10: 0 | C10: 241-060492-0003J | D10: SANDRO OSMANY GUITIERREZ | E10: M | F10: ADMINISTRADOR | G10: =+'Cambio del dia'!G34 -> 36.6243 | H10: =+I10/30 -> 610.405 | I10: 18312.15 | J10: =(I10/30)*K10-'ADMON COM. '!J29 -> 6097.945 | K10: 15 | L10: =+M10*N10 -> 0 | M10: =H10*60% -> 366.243 | N10: 0 | O10: =+J10-P10-Q10 -> 5081.6208 | P10: =+J10/12 -> 508.16208 | Q10: =+P10 -> 508.16208 | R10: =+Q10+O10+P10 -> 6097.945 | S10: =O10+P10 -> 5589.7829 | W10: =T10 -> 0 | X10: =-W10+O10+P10+Q10 -> 6097.945 | Y10: 0 | Z10: =+X10 -> 6097.945 | AA10: 0 | AB10: =X10-Y10-AA10 -> 6097.945 | AD10: 0 | AE10: 0
A11: 2 | B11: 0 | D11: JONATHAN GUTIERREZ | E11: M | F11: BODEGUERO | G11: =+'Cambio del dia'!G35 -> 36.6243 | H11: 500 | I11: 15000 | J11: =(I11/30)*K11 -> 7500 | K11: 15 | L11: =+M11*N11 -> 0 | M11: =H11*60% -> 300 | N11: 0 | O11: =+J11-P11-Q11 -> 6250 | P11: =+J11/12 -> 625 | Q11: =+P11 -> 625 | R11: =+Q11+O11+P11 -> 7500 | S11: =O11+P11 -> 6875 | T11: 0 | W11: =T11 -> 0 | X11: =-W11+O11+P11+Q11 -> 7500 | Y11: 2500 | Z11: =X11-Y11 -> 5000 | AA11: 2000 | AB11: =+Z11-AA11 -> 3000 | AC11: 0 | AD11: =+AA11-AB11 -> -1000 | AE11: 0 | AF11: =X11-AB11-AE11 -> 4500 | AH11: 0.155 | AI11: =+R11-Q11 -> 6875 | AJ11: =AH11*R11 -> 1162.5 | AL11: 0 | AM11: =0.02*AF11 -> 90 | AN11: =AF11+AJ11+AM11 -> 5752.5
A12: 3 | B12: 0 | D12: JAIRO CANO | E12: M | F12: EBANISTA | G12: =+'Cambio del dia'!G36 -> 36.6243 | H12: 550 | I12: 16500 | J12: =(I12/30)*K12 -> 8250 | K12: 15 | L12: =+M12*N12 -> 0 | M12: =H12*60% -> 330 | N12: 0 | O12: =+J12-P12-Q12 -> 6875 | P12: =+J12/12 -> 687.5 | Q12: =+P12 -> 687.5 | R12: =+Q12+O12+P12 -> 8250 | S12: =O12+P12 -> 7562.5 | W12: =T12 -> 0 | X12: =-W12+O12+P12+Q12 -> 8250 | Y12: 0 | Z12: =X12 -> 8250 | AA12: 0 | AB12: =X12-Y12-AA12 -> 8250 | AD12: 0 | AE12: 0
A13: 1 | B13: 0 | C13: 604-011198-1001J | D13: BERMAN VICENTE MONTALVAN MARTINEZ | E13: M | F13: EBANISTA | G13: =+'Cambio del dia'!G36 -> 36.6243 | H13: 1000 | I13: 30000 | J13: =(I13/30)*K13 -> 13000 | K13: 13 | L13: =+M13*N13 -> 0 | M13: =H13*60% -> 600 | N13: 0 | O13: =+J13-P13-Q13 -> 10833.333 | P13: =+J13/12 -> 1083.3333 | Q13: =+P13 -> 1083.3333 | R13: =+Q13+O13+P13 -> 13000 | S13: =O13+P13 -> 11916.667 | W13: =T13 -> 0 | X13: =-W13+O13+P13+Q13 -> 13000 | Y13: 0 | Z13: =X13 -> 13000 | AA13: 0 | AB13: =X13-Y13-AA13 -> 13000 | AD13: 0 | AE13: 0
A14: 1 | B14: 0 | C14: 0 | D14: MARIO AZAEL REYES MARTINEZ | E14: M | F14: AYUD/EBANISTA | G14: =+'Cambio del dia'!G37 -> 36.6243 | H14: 300 | I14: 9000 | J14: =(I14/30)*K14 -> 1800 | K14: 6 | L14: =+M14*N14 -> 0 | M14: =H14*60% -> 180 | N14: 0 | O14: =+J14-P14-Q14 -> 1500 | P14: =+J14/12 -> 150 | Q14: =+P14 -> 150 | R14: =+Q14+O14+P14 -> 1800 | S14: =O14+P14 -> 1650 | W14: =T14 -> 0 | X14: =-W14+O14+P14+Q14 -> 1800 | Y14: 0 | Z14: =X14 -> 1800 | AA14: 0 | AB14: =X14-Y14-AA14 -> 1800 | AD14: 0 | AE14: 0
A15: TOTALES | F15: =SUM(F14) -> 0 | G15: =SUM(G14:G14) -> 36.6243 | H15: =SUM(H10:H12) -> 1660.405 | I15: =SUM(I10:I12) -> 49812.15 | J15: =SUM(J10:J12) -> 21847.945 | K15: =SUM(K10:K12) -> 45 | L15: =SUM(L10:L12) -> 0 | M15: =SUM(M10:M12) -> 996.243 | N15: =SUM(N10:N12) -> 0 | O15: =SUM(O10:O12) -> 18206.621 | ... R15: =SUM(R10:R12) -> 21847.945 | S15: =SUM(S12:S14) -> 21129.167 | T15: =SUM(T12:T14) -> 0 | U15: =SUM(U12:U14) -> 0 | V15: =SUM(V12:V14) -> 0 | W15: =SUM(W12:W14) -> 0 | X15: =SUM(X10:X14) -> 36647.945 | Y15: =SUM(Y10:Y14) -> 2500 | Z15: =X15-Y15 -> 34147.945 | AA15: =SUM(AA10:AA14) -> 2000 | AB15: =SUM(AB10:AB14) -> 32147.945 | AC15: "EL SEÑOR ES MI PASTOR, NADA ME FALTARA" | AD15: =SUM(AD14:AD14) -> 0 | AE15: =SUM(AE14:AE14) -> 0
H17: 10
H18: 350 | I18: 35.6948 | J18: =+H18*I18 -> 12493.18
J19: =+H18/I18 -> 9.8053498 | K19: =9.81*30 -> 294.3
C31: ELABORADO POR: | K31: REVISADO POR: | AB31: AUTORIZADO POR:
C32: Jose Martin Conrrado | K32: IVAN OROZCO OSEJO | AB32: LIC:OSMAN G GUTIERREZ MORENO

Sheet FINCA INSS 
A2: AGRÍCOLA SANTA ISABEL | AH2: B DIA
A3: PLANILLA DE SALARIO QUINCENAL
A4: =+ADMON!A5 -> QUINCENA DEL 16 AL 30 DE ABRIL - 2026
A8: No | B8: INSS | C8: NUMERO DE CEDULA | D8: NOMBRES Y APELLIDOS | E8: GENERO | F8: CARGO | G8: SALARIO DIARIO | H8: SALARIO MENSUAL | I8: I N G R E S O S | Q8: RETENCIONES | W8: TOTAL | Z8: FINCA | AB8: NETO A PAGAR | AC8: COMISARIATO | AD8: SALARIO DEVENGADO | AE8: FIRMAS | AH8: INSS PATRONAL | AI8: VACACIONES | AJ8: 13VO MES | AK8: INATEC 2% | AL8: TOTAL GASTOS NOMINAS
I9: SALARIO QUINCENAL | J9: DIAS LABORADOS | K9: total subcidio | L9: subcidio por dia | M9: DIAS SUBSIDIO | N9: TOTAL BASICO | O9: VACACIONES | P9: 13VO MES | Q9: TOTAL | S9: INSS | T9: IR | U9: ABONO POR PRESTAMOS | V9: TOTAL RETENCION | X9: ALIMENTACION | Y9: DEVENGADO | AA9: TOTAL
A11: 1 | B11: 23724864 | C11: 241-240972-0016G | D11: WILFREDO ARGEÑAL BLANDON | E11: M | F11: BODEGUERO | G11: 400 | H11: 12000 | I11: =(H11/30)*J11 -> 0 | J11: 0 | K11: =+L11*M11 -> 0 | L11: =G11*60% -> 240 | M11: 0 | N11: =+I11-O11-P11 -> 0 | O11: =+I11/12 -> 0 | P11: =+O11 -> 0 | Q11: =+P11+N11+O11 -> 0 | R11: =N11+O11 -> 0 | S11: =+R11*5% -> 0 | V11: =S11 -> 0 | W11: =-V11+N11+O11+P11 -> 0 | Y11: =W11 -> 0 | Z11: 0 | AA11: 0 | AB11: =+Y11-Z11 -> 0 | AC11: 195 | AD11: =W11-Z11-AC11 -> -195 | AF11: 0.155 | AG11: =+Q11-P11 -> 0 | AH11: =AF11*Q11 -> 0 | AJ11: 0 | AK11: =0.02*AD11 -> -3.9 | AL11: =AD11+AH11+AK11 -> -198.9
A12: 2 | B12: 12762134 | D12: ERICK MANUEL GARCIA | E12: M | F12: SOLDADOR | G12: 241 | H12: 6960 | I12: =(H12/30)*J12 -> 0 | J12: 0 | K12: =+L12*M12 -> 0 | L12: =G12*60% -> 144.6 | M12: 0 | N12: =+I12-O12-P12 -> 0 | O12: =I12/12 -> 0 | P12: =O12 -> 0 | Q12: =+P12+N12+O12 -> 0 | R12: =N12+O12 -> 0 | S12: =+R12*5% -> 0 | V12: =S12 -> 0 | W12: =-V12+N12+O12+P12 -> 0 | X12: 0 | Y12: =W12+X12 -> 0 | Z12: 0 | AA12: 0 | AB12: =+Y12-Z12 -> 0 | AC12: 0 | AD12: =+Y12-Z12-AC12 -> 0 | AF12: 0.155 | AG12: =+Q12-P12 -> 0 | AH12: =AF12*Q12 -> 0 | AJ12: 0 | AK12: =0.02*AD12 -> 0 | AL12: =AD12+AH12+AK12 -> 0
A13: 3 | B13: 12762134 | D13: ANGEL JAVIER GARCIA | E13: M | F13: BODEGUERO | G13: 350 | H13: 10500 | I13: =(H13/30)*J13 -> 0 | J13: 0 | K13: =+L13*M13 -> 0 | L13: =G13*60% -> 210 | M13: 0 | N13: =+I13-O13-P13 -> 0 | O13: =+I13/12 -> 0 | P13: =+O13 -> 0 | Q13: =+P13+N13+O13 -> 0 | R13: =N13+O13 -> 0 | S13: =+R13*5% -> 0 | V13: =S13 -> 0 | W13: =-V13+N13+O13+P13 -> 0 | X13: 750 | Y13: =W13 -> 0 | Z13: 0 | AC13: 0 | AD13: =W13-Z13-AC13 -> 0 | AF13: 0.155 | AG13: =+Q13-P13 -> 0 | AH13: =AF13*Q13 -> 0 | AJ13: 0 | AK13: =0.02*AD13 -> 0 | AL13: =AD13+AH13+AK13 -> 0
A14: 4 | B14: 0 | D14: ALBA SUYEN RODA PASOS | E14: F | F14: PLANILLERA | G14: 350 | H14: 10500 | I14: =(H14/30)*J14 -> 0 | J14: 0 | K14: =+L14*M14 -> 0 | L14: =G14*60% -> 210 | M14: 0 | N14: =+I14-O14-P14 -> 0 | O14: =+I14/12 -> 0 | P14: =+O14 -> 0 | Q14: =+P14+N14+O14 -> 0 | R14: =N14+O14 -> 0 | S14: =+R14*5% -> 0 | V14: =S14 -> 0 | W14: =-V14+N14+O14+P14 -> 0 | X14: 750 | Y14: =W14 -> 0 | Z14: 0 | AC14: 0 | AD14: =W14-Z14-AC14 -> 0 | AF14: 0.155 | AG14: =+Q14-P14 -> 0 | AH14: =AF14*Q14 -> 0 | AJ14: 0 | AK14: =0.02*AD14 -> 0 | AL14: =AD14+AH14+AK14 -> 0
A15: 2 | B15: 23724864 | D15: 0 | E15: M | F15: SOLDADOR | G15: 0 | H15: 6960 | I15: 0 | J15: 0 | K15: =+L15*M15 -> 0 | L15: =G15*60% -> 0 | N15: =+I15-O15-P15 -> 0 | O15: =+I15/12 -> 0 | P15: =+O15 -> 0 | Q15: =+P15+N15+O15 -> 0 | R15: =N15+O15 -> 0 | S15: =+R15*5% -> 0 | V15: =S15 -> 0 | W15: =-V15+N15+O15+P15 -> 0 | X15: 750 | Y15: =W15 -> 0 | Z15: 0 | AC15: 0 | AD15: 0 | AF15: 0.155 | AG15: =+Q15-P15 -> 0 | AH15: =AF15*Q15 -> 0 | AJ15: 0 | AK15: =0.02*AD15 -> 0 | AL15: =AD15+AH15+AK15 -> 0
A16: SUB TOTAL | G16: =+G11+G12+G15 -> 641 | H16: =+H11+H12+H15 -> 25920 | I16: =SUM(I11:I15) -> 0 | J16: =SUM(J11:J15) -> 0 | K16: =SUM(K11:K15) -> 0 | L16: =SUM(L11:L15) -> 804.6 | M16: =SUM(M11:M15) -> 0 | N16: =SUM(N11:N15) -> 0 | O16: =SUM(O11:O15) -> 0 | P16: =SUM(P11:P15) -> 0 | ... W16: =SUM(W11:W15) -> 0 | X16: 0 | Y16: =W16+X16 -> 0 | Z16: =SUM(Z11:Z15) -> 0 | AA16: 0 | AB16: =+Y16-Z16 -> 0 | AC16: =SUM(AC11:AC15) -> 195 | AD16: =SUM(AD10:AD14) -> -195 | AG16: =+AG11+AG12 -> 0 | AH16: =SUM(AH11:AH15) -> 0 | AI16: =SUM(AI11:AI15) -> 0 | AJ16: =SUM(AJ11:AJ15) -> 0 | AK16: =SUM(AK11:AK15) -> -3.9 | AL16: =SUM(AL11:AL15) -> -198.9
A17: TOTALES | G17: =+G16 -> 641 | H17: =+H16 -> 25920 | I17: =+I16 -> 0 | J17: =+J16 -> 0 | K17: =+K16 -> 0 | L17: =+L16 -> 804.6 | M17: =+M16 -> 0 | N17: =+N16 -> 0 | ... Z17: =+Z16 -> 0 | AA17: 0 | AB17: =+W17-Z17 -> 0 | AC17: =AC16 -> 195 | AD17: =+AB17-AC17 -> -195 | AE17: "EL SEÑOR ES MI PASTOR, NADA ME FALTARA" | AF17: =SUM(#REF!) -> #REF! | AG17: =+AG16 -> 0 | AH17: =+AH16 -> 0 | AI17: =+AI16 -> 0 | AJ17: =+AJ16 -> 0 | AK17: =+AK16 -> -3.9 | AL17: =+AL16 -> -198.9
G19: 10
G20: 350 | H20: 35.6948 | I20: =+G20*H20 -> 12493.18
I21: =+G20/H20 -> 9.8053498 | J21: =9.81*30 -> 294.3
H25: 0
C40: ELABORADO POR: | J40: REVISADO POR: | AD40: AUTORIZADO POR:
C41: WILFREDO ARGEÑAL BLANDON | J41: IVAN OROZCO OSEJO | AD41: LIC:OSMAN G GUTIERREZ MORENO

Sheet BENEFICIO SECO
A2: AGRÍCOLA SANTA ISABEL
A3: PLANILLA DE SALARIO QUINCENAL (BENEFICIO SECO SIN INSS)
A4: =+ADMON!A5 -> QUINCENA DEL 16 AL 30 DE ABRIL - 2026
A8: No | B8: INSS | C8: NUMERO DE CEDULA | D8: NOMBRES Y APELLIDOS | E8: GENERO | F8: CARGO | G8: cambio del dia | H8: SALARIO DIARIO | I8: SALARIO MENSUAL | J8: I N G R E S O S | R8: RETENCIONES | X8: TOTAL | Y8: FINCA | Z8: NETO A PAGAR | AA8: COMISARIATO | AB8: SALARIO DEVENGADO | AC8: FIRMA | AD8: =+P9 -> VACACIONES | AE8: =+Q9 -> 13VO MES
J9: SALARIO QUINCENAL | K9: DIAS LABORADOS | L9: total subcidio | M9: subcidio por dia | N9: DIAS SUBSIDIO | O9: TOTAL BASICO | P9: VACACIONES | Q9: 13VO MES | R9: TOTAL | T9: INSS | U9: IR | V9: ABONO POR PRESTAMOS | W9: TOTAL RETENCION
A11: 1 | B11: 0 | C11: 604-090489-0000R | D11: JAIRO CANO | E11: M | F11: RESPONSABLE DE BODEGA | G11: =+'Cambio del dia'!G31 -> 36.6243 | H11: 500 | I11: =+H11*30 -> 15000 | J11: =(I11)/30*K11 -> 0 | K11: 0 | L11: =+M11*N11 -> 0 | M11: 0 | N11: 0 | O11: =+J11-P11-Q11 -> 0 | P11: =+J11/12 -> 0 | Q11: =+P11 -> 0 | R11: =+Q11+O11+P11 -> 0 | S11: =O11+P11 -> 0 | W11: =T11 -> 0 | X11: =-W11+O11+P11+Q11 -> 0 | Y11: 0 | Z11: =+R11-Y11 -> 0 | AA11: 0 | AB11: =X11-Y11-AA11 -> 0 | AD11: 0 | AE11: 0
D12: JOTHAN MOISES GUTIERREZ CHAVEZ | E12: M | F12: MONTACARGA | H12: 500 | I12: =+H12*30 -> 15000 | J12: =(I12)/30*K12 -> 0 | K12: 0 | O12: =+J12-P12-Q12 -> 0 | P12: =+J12/12 -> 0 | Q12: =+P12 -> 0 | R12: =+Q12+O12+P12 -> 0 | X12: =-W12+O12+P12+Q12 -> 0 | Y12: 0 | Z12: =+R12-Y12 -> 0 | AA12: 1994 | AB12: =X12-Y12-AA12 -> -1994
A13: TOTALES | G13: =SUM(#REF!) -> #REF! | H13: =SUM(H11:H12) -> 1000 | I13: =SUM(I11:I12) -> 30000 | J13: =SUM(J11:J12) -> 0 | K13: =SUM(K11:K12) -> 0 | L13: =SUM(L11:L12) -> 0 | M13: =SUM(M11:M12) -> 0 | N13: =SUM(N11:N12) -> 0 | O13: =SUM(O11:O12) -> 0 | ... Y13: =SUM(Y11:Y12) -> 0 | Z13: =+R13-Y13 -> 0 | AA13: =SUM(AA11:AA12) -> 1994 | AB13: =SUM(AB11:AB12) -> -1994 | AC13: "EL SEÑOR ES MI PASTOR, NADA ME FALTARA" | AD13: =SUM(#REF!) -> #REF! | AE13: =SUM(#REF!) -> #REF!
D20: ELABORADO POR: | L20: REVISADO POR: | AC20: AUTORIZADO POR:
D21: WILFREDO ARGEÑAL BLANDON | L21: IVAN OROZCO OSEJO | AC21: LIC: OSMAN G GUTIERREZ MORENO

Sheet Hoja3

Sheet COMPLEMENTO DE SALARIO
A1: AGRICOLA-SANTA ISABEL
A2: COMPLEMENTO DE SALARIO DEL 16 AL 30 DE ABRIL 2026
A3: COMPLEMENTO
A5: No. | B5: NOMBRES Y APELLIDOS | C5: DEVENGADO | F5: COMISARIATO | G5: NETO A PAGAR | H5: RECIBIDO CONFORME
D6: FINCA | E6: DEVENGADO | Q6: =+#REF! -> #REF!
A7: 1 | B7: KEYLIN JOHANA MARTINEZ PEREZ | C7: =M14 -> 3409.2 | D7: 0 | E7: =C7-D7 -> 3409.2 | G7: =+E7-F7 -> 3409.2
A8: 2 | B8: IVAN OROZCO OSEJO | C8: 1600 | D8: 0 | E8: =C8-D8 -> 1600 | G8: =+E8-F8 -> 1600
A9: 3 | C9: 0 | D9: 0 | E9: =C9-D9 -> 0 | F9: 0 | G9: =+E9-F9 -> 0
A10: 3 | B10: MARIA ULDA GARCIA RIVAS | C10: 0 | D10: 0 | E10: =C10-D10 -> 0 | G10: =+E10-F10 -> 0
A11: 3 | B11: =+'ADMON COM. '!D21 -> ARMANDO GUIDO GONZALEZ | C11: 0 | D11: 0 | E11: =C11-D11 -> 0 | G11: =+E11-F11 -> 0
A12: Subtotal | C12: =SUM(C7:C11) -> 5009.2 | D12: =SUM(D7:D11) -> 0 | E12: =SUM(E7:E11) -> 5009.2 | F12: =SUM(F7:F11) -> 0 | G12: =SUM(G7:G11) -> 5009.2 | H12: 'EL SEÑOR ES MI PASTOR NADA ME FALTARA''
L14: =177.28*ADMON!L19 -> 2659.2 | M14: =L14+L17 -> 3409.2
M15: 2659.25
M16: 6409.25
B17: AUTORIZADO POR: | E17: REVISADO | L17: =ADMON!L19*50 -> 750
B18: Lic. Osman G. Gutierrez Moreno Ivan Orozco osejo | L18: =50*ADMON!L19 -> 750

Sheet VIATICOS PERS ACOPIO
A1: AGRICOLA SANTA ISABEL
A2: VIATICO PAGADO A PERSONAL DE ACOPIO
A3: QUINCENA DEL 16 AL 28 DE FEBRERO 2025
A4: N/O | B4: NOMBRE Y APELLIDOS | C4: LUGAR DE ACOPIO | D4: DIAS | E4: VALOR | F4: TOTAL | G4: FIRMA
A5: 15 | B5: MARIA ULDA GARCIA RIVAS | C5: ABICINIA/ INSS | D5: 0 | E5: 80 | F5: =(D5)*E5 -> 0
A6: 16 | B6: JOLMAN ARCENIO HIDALGO GONZALEZ | C6: ABICINIA/ INSS | D6: 0 | E6: 80 | F6: =(D6)*E6 -> 0
F7: =SUM(F5:F6) -> 0
B17: _______________________________ | D17: ______________________________
B18: REVISADO | D18: ACTORIZADO
